<!-- See LICENSE.md for legal notices. LICENSE.md must be kept together with this file. -->
<mujoco>
    <body pos="0.1 0 0.25" euler="1.5708 0 1.5708">

            <!-- finger 2 -->
            <body name="link_4.0" pos="0 0 0.00003">
                <inertial pos="0 0 0" quat="0.707107 0.707107 0 0" mass="0.0119" diaginertia="1.01667e-06 1.01667e-06 6.47677e-07" />
                <joint name="joint_4.0" pos="0 0 0" axis="0 0 1" limited="true" range="-0.47 0.47" damping="1" frictionloss="1" stiffness="1"/>
                <geom  class="robot0:Finger" type="mesh" mesh="link_0.0" rgba="0.2 0.2 0.2 1"/>
                <geom  class="robot0:D_Contact" type="mesh" mesh="link_0.0" rgba="0.2 0.2 0.2 1"/>

                <body name="link_5.0" pos="0 0 0.0164">
                    <inertial pos="0 0 0" quat="0.702596 0.559386 -0.178354 0.402039" mass="0.065" diaginertia="6.12799e-05 6.12799e-05 6.12799e-05" />
                    <joint name="joint_5.0" pos="0 0 0" axis="0 1 0" limited="true" range="-0.196 1.61" damping="3" frictionloss="5" />
                    <geom  class="robot0:Finger" type="mesh" mesh="link_1.0" rgba="0.2 0.2 0.2 1"/>
                    <geom  class="robot0:D_Contact" type="mesh" mesh="link_1.0" rgba="0.2 0.2 0.2 1"/>

                    <!-- tactile pad -->
                    <body name="link_5.0_middle" pos="0.01 -0.01 0.015" euler="0 0 0">
                        <inertial pos="0 0 0" quat="0.719796 0.528175 -0.157463 0.422055" mass="0.01" diaginertia="9.99999e-07 -9.92483e-07 9.92475e-07" />
                        <geom  class="robot0:Pad" pos="0 0 0"  type="mesh" mesh="link_middle" rgba="0.9 0.9 0.9 1" euler="0 0 0" />
                        <geom  class="robot0:D_Contact" pos="0 0 0"  type="mesh" mesh="link_middle" rgba="0.9 0.9 0.9 1" euler="0 0 0" />

                        <!--tactile sensor for link 5.0 -->
<!--                        <body name="link_5.0_tactile" pos="0.000 0 0">-->
<!--                            <body name="touch_5_1_1" pos=" 0.00414 0.01752 0.024 "  euler=" 0.0 0.0 0.485">\-->

<!--                            <geom name="touch_5_1_1"   class="robot0:Tactile" friction="0.5 0.5 0.005" mesh="tactile_sphere1" pos="-0.0005 0 0" quat="0.707107 0 0.707107 0"/>-->
<!--                            <geom name="touch_5_1_1"   class="robot0:D_Contact" friction="0.5 0.5 0.005" mesh="tactile_sphere1" pos="-0.0005 0 0" quat="0.707107 0 0.707107 0"/>-->
<!--                            </body>-->

<!--                            <body name="touch_5_2_1" pos=" 0.005265 0.01463 0.024 "  euler=" 0.0 0.0 0.1777">\-->

<!--                            <geom name="touch_5_2_1"   class="robot0:Tactile" friction="0.5 0.5 0.005" mesh="tactile_sphere1" pos="-0.0005 0 0" quat="0.707107 0 0.707107 0"/>-->
<!--                            <geom name="touch_5_2_1"   class="robot0:D_Contact" friction="0.5 0.5 0.005" mesh="tactile_sphere1" pos="-0.0005 0 0" quat="0.707107 0 0.707107 0"/>-->
<!--                            </body>-->

<!--                            <body name="touch_5_3_1" pos=" 0.00581 0.01154 0.024"  euler=" 0.0 0.0 0.0">\-->

<!--                            <geom name="touch_5_3_1"   class="robot0:Tactile" friction="0.5 0.5 0.005" mesh="tactile_sphere1" pos="-0.0005 0 0" quat="0.707107 0 0.707107 0"/>-->
<!--                            <geom name="touch_5_3_1"   class="robot0:D_Contact" friction="0.5 0.5 0.005" mesh="tactile_sphere1" pos="-0.0005 0 0" quat="0.707107 0 0.707107 0"/>-->
<!--                            </body>-->

<!--                            <body name="touch_5_4_1" pos=" 0.00581 0.00846 0.024 "  euler=" 0.0 0.0 0.0">\-->

<!--                            <geom name="touch_5_4_1"   class="robot0:Tactile" friction="0.5 0.5 0.005" mesh="tactile_sphere1" pos="-0.0005 0 0" quat="0.707107 0 0.707107 0"/>-->
<!--                            <geom name="touch_5_4_1"   class="robot0:D_Contact" friction="0.5 0.5 0.005" mesh="tactile_sphere1" pos="-0.0005 0 0" quat="0.707107 0 0.707107 0"/>-->
<!--                            </body>-->

<!--                            <body name="touch_5_5_1" pos=" 0.005265 0.00537 0.024 "  euler=" 0.0 0.0 -0.1777">\-->

<!--                            <geom name="touch_5_5_1"   class="robot0:Tactile" friction="0.5 0.5 0.005" mesh="tactile_sphere1" pos="-0.0005 0 0" quat="0.707107 0 0.707107 0"/>-->
<!--                            <geom name="touch_5_5_1"   class="robot0:D_Contact" friction="0.5 0.5 0.005" mesh="tactile_sphere1" pos="-0.0005 0 0" quat="0.707107 0 0.707107 0"/>-->
<!--                            </body>-->


<!--                            <body name="touch_5_6_1" pos=" 0.00414 0.00248 0.024 "  euler=" 0.0 0.0 -0.485">\-->

<!--                            <geom name="touch_5_6_1"   class="robot0:Tactile" friction="0.5 0.5 0.005" mesh="tactile_sphere1" pos="-0.0005 0 0" quat="0.707107 0 0.707107 0"/>-->
<!--                            <geom name="touch_5_6_1"   class="robot0:D_Contact" friction="0.5 0.5 0.005" mesh="tactile_sphere1" pos="-0.0005 0 0" quat="0.707107 0 0.707107 0"/>-->
<!--                            </body>-->

<!--                            <body name="touch_5_1_2" pos=" 0.00414 0.01752 0.02 "  euler=" 0.0 0.0 0.485">\-->

<!--                            <geom name="touch_5_1_2"   class="robot0:Tactile" friction="0.5 0.5 0.005" mesh="tactile_sphere1" pos="-0.0005 0 0" quat="0.707107 0 0.707107 0"/>-->
<!--                            <geom name="touch_5_1_2"   class="robot0:D_Contact" friction="0.5 0.5 0.005" mesh="tactile_sphere1" pos="-0.0005 0 0" quat="0.707107 0 0.707107 0"/>-->
<!--                            </body>-->

<!--                            <body name="touch_5_2_2" pos=" 0.005265 0.01463 0.02 "  euler=" 0.0 0.0 0.1777">\-->

<!--                            <geom name="touch_5_2_2"   class="robot0:Tactile" friction="0.5 0.5 0.005" mesh="tactile_sphere1" pos="-0.0005 0 0" quat="0.707107 0 0.707107 0"/>-->
<!--                            <geom name="touch_5_2_2"   class="robot0:D_Contact" friction="0.5 0.5 0.005" mesh="tactile_sphere1" pos="-0.0005 0 0" quat="0.707107 0 0.707107 0"/>-->
<!--                            </body>-->

<!--                            <body name="touch_5_3_2" pos=" 0.00581 0.01154 0.02"  euler=" 0.0 0.0 0.0">\-->

<!--                            <geom name="touch_5_3_2"   class="robot0:Tactile" friction="0.5 0.5 0.005" mesh="tactile_sphere1" pos="-0.0005 0 0" quat="0.707107 0 0.707107 0"/>-->
<!--                            <geom name="touch_5_3_2"   class="robot0:D_Contact" friction="0.5 0.5 0.005" mesh="tactile_sphere1" pos="-0.0005 0 0" quat="0.707107 0 0.707107 0"/>-->
<!--                            </body>-->

<!--                            <body name="touch_5_4_2" pos=" 0.00581 0.00846 0.02 "  euler=" 0.0 0.0 0.0">\-->

<!--                            <geom name="touch_5_4_2"   class="robot0:Tactile" friction="0.5 0.5 0.005" mesh="tactile_sphere1" pos="-0.0005 0 0" quat="0.707107 0 0.707107 0"/>-->
<!--                            <geom name="touch_5_4_2"   class="robot0:D_Contact" friction="0.5 0.5 0.005" mesh="tactile_sphere1" pos="-0.0005 0 0" quat="0.707107 0 0.707107 0"/>-->
<!--                            </body>-->

<!--                            <body name="touch_5_5_2" pos=" 0.005265 0.00537 0.02 "  euler=" 0.0 0.0 -0.1777">\-->

<!--                            <geom name="touch_5_5_2"   class="robot0:Tactile" friction="0.5 0.5 0.005" mesh="tactile_sphere1" pos="-0.0005 0 0" quat="0.707107 0 0.707107 0"/>-->
<!--                            <geom name="touch_5_5_2"   class="robot0:D_Contact" friction="0.5 0.5 0.005" mesh="tactile_sphere1" pos="-0.0005 0 0" quat="0.707107 0 0.707107 0"/>-->
<!--                            </body>-->

<!--                            <body name="touch_5_6_2" pos=" 0.00414 0.00248 0.02 "  euler=" 0.0 0.0 -0.485">\-->

<!--                            <geom name="touch_5_6_2"   class="robot0:Tactile" friction="0.5 0.5 0.005" mesh="tactile_sphere1" pos="-0.0005 0 0" quat="0.707107 0 0.707107 0"/>-->
<!--                            <geom name="touch_5_6_2"   class="robot0:D_Contact" friction="0.5 0.5 0.005" mesh="tactile_sphere1" pos="-0.0005 0 0" quat="0.707107 0 0.707107 0"/>-->
<!--                            </body>-->

<!--                            <body name="touch_5_1_3" pos=" 0.00414 0.01752 0.016 "  euler=" 0.0 0.0 0.485">\-->

<!--                            <geom name="touch_5_1_3"   class="robot0:Tactile" friction="0.5 0.5 0.005" mesh="tactile_sphere1" pos="-0.0005 0 0" quat="0.707107 0 0.707107 0"/>-->
<!--                            <geom name="touch_5_1_3"   class="robot0:D_Contact" friction="0.5 0.5 0.005" mesh="tactile_sphere1" pos="-0.0005 0 0" quat="0.707107 0 0.707107 0"/>-->
<!--                            </body>-->

<!--                            <body name="touch_5_2_3" pos=" 0.005265 0.01463 0.016 "  euler=" 0.0 0.0 0.1777">\-->

<!--                            <geom name="touch_5_2_3"   class="robot0:Tactile" friction="0.5 0.5 0.005" mesh="tactile_sphere1" pos="-0.0005 0 0" quat="0.707107 0 0.707107 0"/>-->
<!--                            <geom name="touch_5_2_3"   class="robot0:D_Contact" friction="0.5 0.5 0.005" mesh="tactile_sphere1" pos="-0.0005 0 0" quat="0.707107 0 0.707107 0"/>-->
<!--                            </body>-->

<!--                            <body name="touch_5_3_3" pos=" 0.00581 0.01154 0.016"  euler=" 0.0 0.0 0.0">\-->

<!--                            <geom name="touch_5_3_3"   class="robot0:Tactile" friction="0.5 0.5 0.005" mesh="tactile_sphere1" pos="-0.0005 0 0" quat="0.707107 0 0.707107 0"/>-->
<!--                            <geom name="touch_5_3_3"   class="robot0:D_Contact" friction="0.5 0.5 0.005" mesh="tactile_sphere1" pos="-0.0005 0 0" quat="0.707107 0 0.707107 0"/>-->
<!--                            </body>-->

<!--                            <body name="touch_5_4_3" pos=" 0.00581 0.00846 0.016 "  euler=" 0.0 0.0 0.0">\-->

<!--                            <geom name="touch_5_4_3"   class="robot0:Tactile" friction="0.5 0.5 0.005" mesh="tactile_sphere1" pos="-0.0005 0 0" quat="0.707107 0 0.707107 0"/>-->
<!--                            <geom name="touch_5_4_3"   class="robot0:D_Contact" friction="0.5 0.5 0.005" mesh="tactile_sphere1" pos="-0.0005 0 0" quat="0.707107 0 0.707107 0"/>-->
<!--                            </body>-->

<!--                            <body name="touch_5_5_3" pos=" 0.005265 0.00537 0.016 "  euler=" 0.0 0.0 -0.1777">\-->

<!--                            <geom name="touch_5_5_3"   class="robot0:Tactile" friction="0.5 0.5 0.005" mesh="tactile_sphere1" pos="-0.0005 0 0" quat="0.707107 0 0.707107 0"/>-->
<!--                            <geom name="touch_5_5_3"   class="robot0:D_Contact" friction="0.5 0.5 0.005" mesh="tactile_sphere1" pos="-0.0005 0 0" quat="0.707107 0 0.707107 0"/>-->
<!--                            </body>-->

<!--                            <body name="touch_5_6_3" pos=" 0.00414 0.00248 0.016 "  euler=" 0.0 0.0 -0.485">\-->

<!--                            <geom name="touch_5_6_3"   class="robot0:Tactile" friction="0.5 0.5 0.005" mesh="tactile_sphere1" pos="-0.0005 0 0" quat="0.707107 0 0.707107 0"/>-->
<!--                            <geom name="touch_5_6_3"   class="robot0:D_Contact" friction="0.5 0.5 0.005" mesh="tactile_sphere1" pos="-0.0005 0 0" quat="0.707107 0 0.707107 0"/>-->
<!--                            </body>-->


<!--                            <body name="touch_5_1_4" pos=" 0.00414 0.01752 0.012 "  euler=" 0.0 0.0 0.485">\-->

<!--                            <geom name="touch_5_1_4"   class="robot0:Tactile" friction="0.5 0.5 0.005" mesh="tactile_sphere1" pos="-0.0005 0 0" quat="0.707107 0 0.707107 0"/>-->
<!--                            <geom name="touch_5_1_4"   class="robot0:D_Contact" friction="0.5 0.5 0.005" mesh="tactile_sphere1" pos="-0.0005 0 0" quat="0.707107 0 0.707107 0"/>-->
<!--                            </body>-->

<!--                            <body name="touch_5_2_4" pos=" 0.005265 0.01463 0.012 "  euler=" 0.0 0.0 0.1777">\-->

<!--                            <geom name="touch_5_2_4"   class="robot0:Tactile" friction="0.5 0.5 0.005" mesh="tactile_sphere1" pos="-0.0005 0 0" quat="0.707107 0 0.707107 0"/>-->
<!--                            <geom name="touch_5_2_4"   class="robot0:D_Contact" friction="0.5 0.5 0.005" mesh="tactile_sphere1" pos="-0.0005 0 0" quat="0.707107 0 0.707107 0"/>-->
<!--                            </body>-->

<!--                            <body name="touch_5_3_4" pos=" 0.00581 0.01154 0.012"  euler=" 0.0 0.0 0.0">\-->

<!--                            <geom name="touch_5_3_4"   class="robot0:Tactile" friction="0.5 0.5 0.005" mesh="tactile_sphere1" pos="-0.0005 0 0" quat="0.707107 0 0.707107 0"/>-->
<!--                            <geom name="touch_5_3_4"   class="robot0:D_Contact" friction="0.5 0.5 0.005" mesh="tactile_sphere1" pos="-0.0005 0 0" quat="0.707107 0 0.707107 0"/>-->
<!--                            </body>-->

<!--                            <body name="touch_5_4_4" pos=" 0.00581 0.00846 0.012 "  euler=" 0.0 0.0 0.0">\-->

<!--                            <geom name="touch_5_4_4"   class="robot0:Tactile" friction="0.5 0.5 0.005" mesh="tactile_sphere1" pos="-0.0005 0 0" quat="0.707107 0 0.707107 0"/>-->
<!--                            <geom name="touch_5_4_4"   class="robot0:D_Contact" friction="0.5 0.5 0.005" mesh="tactile_sphere1" pos="-0.0005 0 0" quat="0.707107 0 0.707107 0"/>-->
<!--                            </body>-->

<!--                            <body name="touch_5_5_4" pos=" 0.005265 0.00537 0.012 "  euler=" 0.0 0.0 -0.1777">\-->

<!--                            <geom name="touch_5_5_4"   class="robot0:Tactile" friction="0.5 0.5 0.005" mesh="tactile_sphere1" pos="-0.0005 0 0" quat="0.707107 0 0.707107 0"/>-->
<!--                            <geom name="touch_5_5_4"   class="robot0:D_Contact" friction="0.5 0.5 0.005" mesh="tactile_sphere1" pos="-0.0005 0 0" quat="0.707107 0 0.707107 0"/>-->
<!--                            </body>-->

<!--                            <body name="touch_5_6_4" pos=" 0.00414 0.00248 0.012 "  euler=" 0.0 0.0 -0.485">\-->

<!--                            <geom name="touch_5_6_4"   class="robot0:Tactile" friction="0.5 0.5 0.005" mesh="tactile_sphere1" pos="-0.0005 0 0" quat="0.707107 0 0.707107 0"/>-->
<!--                            <geom name="touch_5_6_4"   class="robot0:D_Contact" friction="0.5 0.5 0.005" mesh="tactile_sphere1" pos="-0.0005 0 0" quat="0.707107 0 0.707107 0"/>-->
<!--                            </body>-->


<!--                            <body name="touch_5_1_5" pos=" 0.00414 0.01752 0.008 "  euler=" 0.0 0.0 0.485">\-->

<!--                            <geom name="touch_5_1_5"   class="robot0:Tactile" friction="0.5 0.5 0.005" mesh="tactile_sphere1" pos="-0.0005 0 0" quat="0.707107 0 0.707107 0"/>-->
<!--                            <geom name="touch_5_1_5"   class="robot0:D_Contact" friction="0.5 0.5 0.005" mesh="tactile_sphere1" pos="-0.0005 0 0" quat="0.707107 0 0.707107 0"/>-->
<!--                            </body>-->

<!--                            <body name="touch_5_2_5" pos=" 0.005265 0.01463 0.008 "  euler=" 0.0 0.0 0.1777">\-->

<!--                            <geom name="touch_5_2_5"   class="robot0:Tactile" friction="0.5 0.5 0.005" mesh="tactile_sphere1" pos="-0.0005 0 0" quat="0.707107 0 0.707107 0"/>-->
<!--                            <geom name="touch_5_2_5"   class="robot0:D_Contact" friction="0.5 0.5 0.005" mesh="tactile_sphere1" pos="-0.0005 0 0" quat="0.707107 0 0.707107 0"/>-->
<!--                            </body>-->

<!--                            <body name="touch_5_3_5" pos=" 0.00581 0.01154 0.008"  euler=" 0.0 0.0 0.0">\-->

<!--                            <geom name="touch_5_3_5"   class="robot0:Tactile" friction="0.5 0.5 0.005" mesh="tactile_sphere1" pos="-0.0005 0 0" quat="0.707107 0 0.707107 0"/>-->
<!--                            <geom name="touch_5_3_5"   class="robot0:D_Contact" friction="0.5 0.5 0.005" mesh="tactile_sphere1" pos="-0.0005 0 0" quat="0.707107 0 0.707107 0"/>-->
<!--                            </body>-->

<!--                            <body name="touch_5_4_5" pos=" 0.00581 0.00846 0.008 "  euler=" 0.0 0.0 0.0">\-->

<!--                            <geom name="touch_5_4_5"   class="robot0:Tactile" friction="0.5 0.5 0.005" mesh="tactile_sphere1" pos="-0.0005 0 0" quat="0.707107 0 0.707107 0"/>-->
<!--                            <geom name="touch_5_4_5"   class="robot0:D_Contact" friction="0.5 0.5 0.005" mesh="tactile_sphere1" pos="-0.0005 0 0" quat="0.707107 0 0.707107 0"/>-->
<!--                            </body>-->

<!--                            <body name="touch_5_5_5" pos=" 0.005265 0.00537 0.008 "  euler=" 0.0 0.0 -0.1777">\-->

<!--                            <geom name="touch_5_5_5"   class="robot0:Tactile" friction="0.5 0.5 0.005" mesh="tactile_sphere1" pos="-0.0005 0 0" quat="0.707107 0 0.707107 0"/>-->
<!--                            <geom name="touch_5_5_5"   class="robot0:D_Contact" friction="0.5 0.5 0.005" mesh="tactile_sphere1" pos="-0.0005 0 0" quat="0.707107 0 0.707107 0"/>-->
<!--                            </body>-->

<!--                            <body name="touch_5_6_5" pos=" 0.00414 0.00248 0.008 "  euler=" 0.0 0.0 -0.485">\-->

<!--                            <geom name="touch_5_6_5"   class="robot0:Tactile" friction="0.5 0.5 0.005" mesh="tactile_sphere1" pos="-0.0005 0 0" quat="0.707107 0 0.707107 0"/>-->
<!--                            <geom name="touch_5_6_5"   class="robot0:D_Contact" friction="0.5 0.5 0.005" mesh="tactile_sphere1" pos="-0.0005 0 0" quat="0.707107 0 0.707107 0"/>-->
<!--                            </body>-->


<!--                            <body name="touch_5_1_6" pos=" 0.00414 0.01752 0.004 "  euler=" 0.0 0.0 0.485">\-->

<!--                            <geom name="touch_5_1_6"   class="robot0:Tactile" friction="0.5 0.5 0.005" mesh="tactile_sphere1" pos="-0.0005 0 0" quat="0.707107 0 0.707107 0"/>-->
<!--                            <geom name="touch_5_1_6"   class="robot0:D_Contact" friction="0.5 0.5 0.005" mesh="tactile_sphere1" pos="-0.0005 0 0" quat="0.707107 0 0.707107 0"/>-->
<!--                            </body>-->

<!--                            <body name="touch_5_2_6" pos=" 0.005265 0.01463 0.004 "  euler=" 0.0 0.0 0.1777">\-->

<!--                            <geom name="touch_5_2_6"   class="robot0:Tactile" friction="0.5 0.5 0.005" mesh="tactile_sphere1" pos="-0.0005 0 0" quat="0.707107 0 0.707107 0"/>-->
<!--                            <geom name="touch_5_2_6"   class="robot0:D_Contact" friction="0.5 0.5 0.005" mesh="tactile_sphere1" pos="-0.0005 0 0" quat="0.707107 0 0.707107 0"/>-->
<!--                            </body>-->

<!--                            <body name="touch_5_3_6" pos=" 0.00581 0.01154 0.004"  euler=" 0.0 0.0 0.0">\-->

<!--                            <geom name="touch_5_3_6"   class="robot0:Tactile" friction="0.5 0.5 0.005" mesh="tactile_sphere1" pos="-0.0005 0 0" quat="0.707107 0 0.707107 0"/>-->
<!--                            <geom name="touch_5_3_6"   class="robot0:D_Contact" friction="0.5 0.5 0.005" mesh="tactile_sphere1" pos="-0.0005 0 0" quat="0.707107 0 0.707107 0"/>-->
<!--                            </body>-->

<!--                            <body name="touch_5_4_6" pos=" 0.00581 0.00846 0.004 "  euler=" 0.0 0.0 0.0">\-->

<!--                            <geom name="touch_5_4_6"   class="robot0:Tactile" friction="0.5 0.5 0.005" mesh="tactile_sphere1" pos="-0.0005 0 0" quat="0.707107 0 0.707107 0"/>-->
<!--                            <geom name="touch_5_4_6"   class="robot0:D_Contact" friction="0.5 0.5 0.005" mesh="tactile_sphere1" pos="-0.0005 0 0" quat="0.707107 0 0.707107 0"/>-->
<!--                            </body>-->

<!--                            <body name="touch_5_5_6" pos=" 0.005265 0.00537 0.004 "  euler=" 0.0 0.0 -0.1777">\-->

<!--                            <geom name="touch_5_5_6"   class="robot0:Tactile" friction="0.5 0.5 0.005" mesh="tactile_sphere1" pos="-0.0005 0 0" quat="0.707107 0 0.707107 0"/>-->
<!--                            <geom name="touch_5_5_6"   class="robot0:D_Contact" friction="0.5 0.5 0.005" mesh="tactile_sphere1" pos="-0.0005 0 0" quat="0.707107 0 0.707107 0"/>-->
<!--                            </body>-->

<!--                            <body name="touch_5_6_6" pos=" 0.00414 0.00248 0.004 "  euler=" 0.0 0.0 -0.485">\-->

<!--                            <geom name="touch_5_6_6"   class="robot0:Tactile" friction="0.5 0.5 0.005" mesh="tactile_sphere1" pos="-0.0005 0 0" quat="0.707107 0 0.707107 0"/>-->
<!--                            <geom name="touch_5_6_6"   class="robot0:D_Contact" friction="0.5 0.5 0.005" mesh="tactile_sphere1" pos="-0.0005 0 0" quat="0.707107 0 0.707107 0"/>-->
<!--                            </body>-->

<!--                        </body>-->

                    </body>

                    <body name="link_6.0" pos="0 0 0.054">
                        <inertial pos="0 0 0" quat="0.719796 0.528175 -0.157463 0.422055" mass="0.0355" diaginertia="2.20969e-05 2.20969e-05 2.20969e-05" />
                        <joint name="joint_6.0" pos="0 0 0" axis="0 1 0" limited="true" range="-0.174 1.709" damping="1" frictionloss="1" stiffness="1" />
                        <geom  class="robot0:Finger" type="mesh" mesh="link_2.0" rgba="0.2 0.2 0.2 1"/>
                        <geom  class="robot0:D_Contact" type="mesh" mesh="link_2.0" rgba="0.2 0.2 0.2 1"/>
                        <!-- tactile pad -->
                        <body name="link_6.0_middle" pos="0.01 -0.01 0.015" euler="0 0 0">
                            <inertial pos="0 0 0" quat="0.719796 0.528175 -0.157463 0.422055" mass="0.01" diaginertia="9.99999e-07 -9.92483e-07 9.92475e-07" />
                            <geom  class="robot0:Pad" pos="0 0 0"  type="mesh" mesh="link_middle" rgba="0.9 0.9 0.9 1" euler="0 0 0" />
                            <geom  class="robot0:D_Contact" pos="0 0 0"  type="mesh" mesh="link_middle" rgba="0.9 0.9 0.9 1" euler="0 0 0" />

                            <!--tactile sensor for link 6.0 -->
<!--                            <body name="link_6.0_tactile" pos="0.000 0 0">-->
<!--                            <body name="touch_4_1_1" pos=" 0.00414 0.01752 0.024 "  euler=" 0.0 0.0 0.485">\-->

<!--                            <geom name="touch_4_1_1"   class="robot0:Tactile" friction="0.5 0.5 0.005" mesh="tactile_sphere1" pos="-0.0005 0 0" quat="0.707107 0 0.707107 0"/>-->
<!--                            <geom name="touch_4_1_1"   class="robot0:D_Contact" friction="0.5 0.5 0.005" mesh="tactile_sphere1" pos="-0.0005 0 0" quat="0.707107 0 0.707107 0"/>-->
<!--                            </body>-->

<!--                            <body name="touch_4_2_1" pos=" 0.005265 0.01463 0.024 "  euler=" 0.0 0.0 0.1777">\-->

<!--                            <geom name="touch_4_2_1"   class="robot0:Tactile" friction="0.5 0.5 0.005" mesh="tactile_sphere1" pos="-0.0005 0 0" quat="0.707107 0 0.707107 0"/>-->
<!--                            <geom name="touch_4_2_1"   class="robot0:D_Contact" friction="0.5 0.5 0.005" mesh="tactile_sphere1" pos="-0.0005 0 0" quat="0.707107 0 0.707107 0"/>-->
<!--                            </body>-->

<!--                            <body name="touch_4_3_1" pos=" 0.00581 0.01154 0.024"  euler=" 0.0 0.0 0.0">\-->

<!--                            <geom name="touch_4_3_1"   class="robot0:Tactile" friction="0.5 0.5 0.005" mesh="tactile_sphere1" pos="-0.0005 0 0" quat="0.707107 0 0.707107 0"/>-->
<!--                            <geom name="touch_4_3_1"   class="robot0:D_Contact" friction="0.5 0.5 0.005" mesh="tactile_sphere1" pos="-0.0005 0 0" quat="0.707107 0 0.707107 0"/>-->
<!--                            </body>-->

<!--                            <body name="touch_4_4_1" pos=" 0.00581 0.00846 0.024 "  euler=" 0.0 0.0 0.0">\-->

<!--                            <geom name="touch_4_4_1"   class="robot0:Tactile" friction="0.5 0.5 0.005" mesh="tactile_sphere1" pos="-0.0005 0 0" quat="0.707107 0 0.707107 0"/>-->
<!--                            <geom name="touch_4_4_1"   class="robot0:D_Contact" friction="0.5 0.5 0.005" mesh="tactile_sphere1" pos="-0.0005 0 0" quat="0.707107 0 0.707107 0"/>-->
<!--                            </body>-->

<!--                            <body name="touch_4_5_1" pos=" 0.005265 0.00537 0.024 "  euler=" 0.0 0.0 -0.1777">\-->

<!--                            <geom name="touch_4_5_1"   class="robot0:Tactile" friction="0.5 0.5 0.005" mesh="tactile_sphere1" pos="-0.0005 0 0" quat="0.707107 0 0.707107 0"/>-->
<!--                            <geom name="touch_4_5_1"   class="robot0:D_Contact" friction="0.5 0.5 0.005" mesh="tactile_sphere1" pos="-0.0005 0 0" quat="0.707107 0 0.707107 0"/>-->
<!--                            </body>-->


<!--                            <body name="touch_4_6_1" pos=" 0.00414 0.00248 0.024 "  euler=" 0.0 0.0 -0.485">\-->

<!--                            <geom name="touch_4_6_1"   class="robot0:Tactile" friction="0.5 0.5 0.005" mesh="tactile_sphere1" pos="-0.0005 0 0" quat="0.707107 0 0.707107 0"/>-->
<!--                            <geom name="touch_4_6_1"   class="robot0:D_Contact" friction="0.5 0.5 0.005" mesh="tactile_sphere1" pos="-0.0005 0 0" quat="0.707107 0 0.707107 0"/>-->
<!--                            </body>-->

<!--                            <body name="touch_4_1_2" pos=" 0.00414 0.01752 0.02 "  euler=" 0.0 0.0 0.485">\-->

<!--                            <geom name="touch_4_1_2"   class="robot0:Tactile" friction="0.5 0.5 0.005" mesh="tactile_sphere1" pos="-0.0005 0 0" quat="0.707107 0 0.707107 0"/>-->
<!--                            <geom name="touch_4_1_2"   class="robot0:D_Contact" friction="0.5 0.5 0.005" mesh="tactile_sphere1" pos="-0.0005 0 0" quat="0.707107 0 0.707107 0"/>-->
<!--                            </body>-->

<!--                            <body name="touch_4_2_2" pos=" 0.005265 0.01463 0.02 "  euler=" 0.0 0.0 0.1777">\-->

<!--                            <geom name="touch_4_2_2"   class="robot0:Tactile" friction="0.5 0.5 0.005" mesh="tactile_sphere1" pos="-0.0005 0 0" quat="0.707107 0 0.707107 0"/>-->
<!--                            <geom name="touch_4_2_2"   class="robot0:D_Contact" friction="0.5 0.5 0.005" mesh="tactile_sphere1" pos="-0.0005 0 0" quat="0.707107 0 0.707107 0"/>-->
<!--                            </body>-->

<!--                            <body name="touch_4_3_2" pos=" 0.00581 0.01154 0.02"  euler=" 0.0 0.0 0.0">\-->

<!--                            <geom name="touch_4_3_2"   class="robot0:Tactile" friction="0.5 0.5 0.005" mesh="tactile_sphere1" pos="-0.0005 0 0" quat="0.707107 0 0.707107 0"/>-->
<!--                            <geom name="touch_4_3_2"   class="robot0:D_Contact" friction="0.5 0.5 0.005" mesh="tactile_sphere1" pos="-0.0005 0 0" quat="0.707107 0 0.707107 0"/>-->
<!--                            </body>-->

<!--                            <body name="touch_4_4_2" pos=" 0.00581 0.00846 0.02 "  euler=" 0.0 0.0 0.0">\-->

<!--                            <geom name="touch_4_4_2"   class="robot0:Tactile" friction="0.5 0.5 0.005" mesh="tactile_sphere1" pos="-0.0005 0 0" quat="0.707107 0 0.707107 0"/>-->
<!--                            <geom name="touch_4_4_2"   class="robot0:D_Contact" friction="0.5 0.5 0.005" mesh="tactile_sphere1" pos="-0.0005 0 0" quat="0.707107 0 0.707107 0"/>-->
<!--                            </body>-->

<!--                            <body name="touch_4_5_2" pos=" 0.005265 0.00537 0.02 "  euler=" 0.0 0.0 -0.1777">\-->

<!--                            <geom name="touch_4_5_2"   class="robot0:Tactile" friction="0.5 0.5 0.005" mesh="tactile_sphere1" pos="-0.0005 0 0" quat="0.707107 0 0.707107 0"/>-->
<!--                            <geom name="touch_4_5_2"   class="robot0:D_Contact" friction="0.5 0.5 0.005" mesh="tactile_sphere1" pos="-0.0005 0 0" quat="0.707107 0 0.707107 0"/>-->
<!--                            </body>-->

<!--                            <body name="touch_4_6_2" pos=" 0.00414 0.00248 0.02 "  euler=" 0.0 0.0 -0.485">\-->

<!--                            <geom name="touch_4_6_2"   class="robot0:Tactile" friction="0.5 0.5 0.005" mesh="tactile_sphere1" pos="-0.0005 0 0" quat="0.707107 0 0.707107 0"/>-->
<!--                            <geom name="touch_4_6_2"   class="robot0:D_Contact" friction="0.5 0.5 0.005" mesh="tactile_sphere1" pos="-0.0005 0 0" quat="0.707107 0 0.707107 0"/>-->
<!--                            </body>-->

<!--                            <body name="touch_4_1_3" pos=" 0.00414 0.01752 0.016 "  euler=" 0.0 0.0 0.485">\-->

<!--                            <geom name="touch_4_1_3"   class="robot0:Tactile" friction="0.5 0.5 0.005" mesh="tactile_sphere1" pos="-0.0005 0 0" quat="0.707107 0 0.707107 0"/>-->
<!--                            <geom name="touch_4_1_3"   class="robot0:D_Contact" friction="0.5 0.5 0.005" mesh="tactile_sphere1" pos="-0.0005 0 0" quat="0.707107 0 0.707107 0"/>-->
<!--                            </body>-->

<!--                            <body name="touch_4_2_3" pos=" 0.005265 0.01463 0.016 "  euler=" 0.0 0.0 0.1777">\-->

<!--                            <geom name="touch_4_2_3"   class="robot0:Tactile" friction="0.5 0.5 0.005" mesh="tactile_sphere1" pos="-0.0005 0 0" quat="0.707107 0 0.707107 0"/>-->
<!--                            <geom name="touch_4_2_3"   class="robot0:D_Contact" friction="0.5 0.5 0.005" mesh="tactile_sphere1" pos="-0.0005 0 0" quat="0.707107 0 0.707107 0"/>-->
<!--                            </body>-->

<!--                            <body name="touch_4_3_3" pos=" 0.00581 0.01154 0.016"  euler=" 0.0 0.0 0.0">\-->

<!--                            <geom name="touch_4_3_3"   class="robot0:Tactile" friction="0.5 0.5 0.005" mesh="tactile_sphere1" pos="-0.0005 0 0" quat="0.707107 0 0.707107 0"/>-->
<!--                            <geom name="touch_4_3_3"   class="robot0:D_Contact" friction="0.5 0.5 0.005" mesh="tactile_sphere1" pos="-0.0005 0 0" quat="0.707107 0 0.707107 0"/>-->
<!--                            </body>-->

<!--                            <body name="touch_4_4_3" pos=" 0.00581 0.00846 0.016 "  euler=" 0.0 0.0 0.0">\-->

<!--                            <geom name="touch_4_4_3"   class="robot0:Tactile" friction="0.5 0.5 0.005" mesh="tactile_sphere1" pos="-0.0005 0 0" quat="0.707107 0 0.707107 0"/>-->
<!--                            <geom name="touch_4_4_3"   class="robot0:D_Contact" friction="0.5 0.5 0.005" mesh="tactile_sphere1" pos="-0.0005 0 0" quat="0.707107 0 0.707107 0"/>-->
<!--                            </body>-->

<!--                            <body name="touch_4_5_3" pos=" 0.005265 0.00537 0.016 "  euler=" 0.0 0.0 -0.1777">\-->

<!--                            <geom name="touch_4_5_3"   class="robot0:Tactile" friction="0.5 0.5 0.005" mesh="tactile_sphere1" pos="-0.0005 0 0" quat="0.707107 0 0.707107 0"/>-->
<!--                            <geom name="touch_4_5_3"   class="robot0:D_Contact" friction="0.5 0.5 0.005" mesh="tactile_sphere1" pos="-0.0005 0 0" quat="0.707107 0 0.707107 0"/>-->
<!--                            </body>-->

<!--                            <body name="touch_4_6_3" pos=" 0.00414 0.00248 0.016 "  euler=" 0.0 0.0 -0.485">\-->

<!--                            <geom name="touch_4_6_3"   class="robot0:Tactile" friction="0.5 0.5 0.005" mesh="tactile_sphere1" pos="-0.0005 0 0" quat="0.707107 0 0.707107 0"/>-->
<!--                            <geom name="touch_4_6_3"   class="robot0:D_Contact" friction="0.5 0.5 0.005" mesh="tactile_sphere1" pos="-0.0005 0 0" quat="0.707107 0 0.707107 0"/>-->
<!--                            </body>-->


<!--                            <body name="touch_4_1_4" pos=" 0.00414 0.01752 0.012 "  euler=" 0.0 0.0 0.485">\-->

<!--                            <geom name="touch_4_1_4"   class="robot0:Tactile" friction="0.5 0.5 0.005" mesh="tactile_sphere1" pos="-0.0005 0 0" quat="0.707107 0 0.707107 0"/>-->
<!--                            <geom name="touch_4_1_4"   class="robot0:D_Contact" friction="0.5 0.5 0.005" mesh="tactile_sphere1" pos="-0.0005 0 0" quat="0.707107 0 0.707107 0"/>-->
<!--                            </body>-->

<!--                            <body name="touch_4_2_4" pos=" 0.005265 0.01463 0.012 "  euler=" 0.0 0.0 0.1777">\-->

<!--                            <geom name="touch_4_2_4"   class="robot0:Tactile" friction="0.5 0.5 0.005" mesh="tactile_sphere1" pos="-0.0005 0 0" quat="0.707107 0 0.707107 0"/>-->
<!--                            <geom name="touch_4_2_4"   class="robot0:D_Contact" friction="0.5 0.5 0.005" mesh="tactile_sphere1" pos="-0.0005 0 0" quat="0.707107 0 0.707107 0"/>-->
<!--                            </body>-->

<!--                            <body name="touch_4_3_4" pos=" 0.00581 0.01154 0.012"  euler=" 0.0 0.0 0.0">\-->

<!--                            <geom name="touch_4_3_4"   class="robot0:Tactile" friction="0.5 0.5 0.005" mesh="tactile_sphere1" pos="-0.0005 0 0" quat="0.707107 0 0.707107 0"/>-->
<!--                            <geom name="touch_4_3_4"   class="robot0:D_Contact" friction="0.5 0.5 0.005" mesh="tactile_sphere1" pos="-0.0005 0 0" quat="0.707107 0 0.707107 0"/>-->
<!--                            </body>-->

<!--                            <body name="touch_4_4_4" pos=" 0.00581 0.00846 0.012 "  euler=" 0.0 0.0 0.0">\-->

<!--                            <geom name="touch_4_4_4"   class="robot0:Tactile" friction="0.5 0.5 0.005" mesh="tactile_sphere1" pos="-0.0005 0 0" quat="0.707107 0 0.707107 0"/>-->
<!--                            <geom name="touch_4_4_4"   class="robot0:D_Contact" friction="0.5 0.5 0.005" mesh="tactile_sphere1" pos="-0.0005 0 0" quat="0.707107 0 0.707107 0"/>-->
<!--                            </body>-->

<!--                            <body name="touch_4_5_4" pos=" 0.005265 0.00537 0.012 "  euler=" 0.0 0.0 -0.1777">\-->

<!--                            <geom name="touch_4_5_4"   class="robot0:Tactile" friction="0.5 0.5 0.005" mesh="tactile_sphere1" pos="-0.0005 0 0" quat="0.707107 0 0.707107 0"/>-->
<!--                            <geom name="touch_4_5_4"   class="robot0:D_Contact" friction="0.5 0.5 0.005" mesh="tactile_sphere1" pos="-0.0005 0 0" quat="0.707107 0 0.707107 0"/>-->
<!--                            </body>-->

<!--                            <body name="touch_4_6_4" pos=" 0.00414 0.00248 0.012 "  euler=" 0.0 0.0 -0.485">\-->

<!--                            <geom name="touch_4_6_4"   class="robot0:Tactile" friction="0.5 0.5 0.005" mesh="tactile_sphere1" pos="-0.0005 0 0" quat="0.707107 0 0.707107 0"/>-->
<!--                            <geom name="touch_4_6_4"   class="robot0:D_Contact" friction="0.5 0.5 0.005" mesh="tactile_sphere1" pos="-0.0005 0 0" quat="0.707107 0 0.707107 0"/>-->
<!--                            </body>-->


<!--                            <body name="touch_4_1_5" pos=" 0.00414 0.01752 0.008 "  euler=" 0.0 0.0 0.485">\-->

<!--                            <geom name="touch_4_1_5"   class="robot0:Tactile" friction="0.5 0.5 0.005" mesh="tactile_sphere1" pos="-0.0005 0 0" quat="0.707107 0 0.707107 0"/>-->
<!--                            <geom name="touch_4_1_5"   class="robot0:D_Contact" friction="0.5 0.5 0.005" mesh="tactile_sphere1" pos="-0.0005 0 0" quat="0.707107 0 0.707107 0"/>-->
<!--                            </body>-->

<!--                            <body name="touch_4_2_5" pos=" 0.005265 0.01463 0.008 "  euler=" 0.0 0.0 0.1777">\-->

<!--                            <geom name="touch_4_2_5"   class="robot0:Tactile" friction="0.5 0.5 0.005" mesh="tactile_sphere1" pos="-0.0005 0 0" quat="0.707107 0 0.707107 0"/>-->
<!--                            <geom name="touch_4_2_5"   class="robot0:D_Contact" friction="0.5 0.5 0.005" mesh="tactile_sphere1" pos="-0.0005 0 0" quat="0.707107 0 0.707107 0"/>-->
<!--                            </body>-->

<!--                            <body name="touch_4_3_5" pos=" 0.00581 0.01154 0.008"  euler=" 0.0 0.0 0.0">\-->

<!--                            <geom name="touch_4_3_5"   class="robot0:Tactile" friction="0.5 0.5 0.005" mesh="tactile_sphere1" pos="-0.0005 0 0" quat="0.707107 0 0.707107 0"/>-->
<!--                            <geom name="touch_4_3_5"   class="robot0:D_Contact" friction="0.5 0.5 0.005" mesh="tactile_sphere1" pos="-0.0005 0 0" quat="0.707107 0 0.707107 0"/>-->
<!--                            </body>-->

<!--                            <body name="touch_4_4_5" pos=" 0.00581 0.00846 0.008 "  euler=" 0.0 0.0 0.0">\-->

<!--                            <geom name="touch_4_4_5"   class="robot0:Tactile" friction="0.5 0.5 0.005" mesh="tactile_sphere1" pos="-0.0005 0 0" quat="0.707107 0 0.707107 0"/>-->
<!--                            <geom name="touch_4_4_5"   class="robot0:D_Contact" friction="0.5 0.5 0.005" mesh="tactile_sphere1" pos="-0.0005 0 0" quat="0.707107 0 0.707107 0"/>-->
<!--                            </body>-->

<!--                            <body name="touch_4_5_5" pos=" 0.005265 0.00537 0.008 "  euler=" 0.0 0.0 -0.1777">\-->

<!--                            <geom name="touch_4_5_5"   class="robot0:Tactile" friction="0.5 0.5 0.005" mesh="tactile_sphere1" pos="-0.0005 0 0" quat="0.707107 0 0.707107 0"/>-->
<!--                            <geom name="touch_4_5_5"   class="robot0:D_Contact" friction="0.5 0.5 0.005" mesh="tactile_sphere1" pos="-0.0005 0 0" quat="0.707107 0 0.707107 0"/>-->
<!--                            </body>-->

<!--                            <body name="touch_4_6_5" pos=" 0.00414 0.00248 0.008 "  euler=" 0.0 0.0 -0.485">\-->

<!--                            <geom name="touch_4_6_5"   class="robot0:Tactile" friction="0.5 0.5 0.005" mesh="tactile_sphere1" pos="-0.0005 0 0" quat="0.707107 0 0.707107 0"/>-->
<!--                            <geom name="touch_4_6_5"   class="robot0:D_Contact" friction="0.5 0.5 0.005" mesh="tactile_sphere1" pos="-0.0005 0 0" quat="0.707107 0 0.707107 0"/>-->
<!--                            </body>-->


<!--                            <body name="touch_4_1_6" pos=" 0.00414 0.01752 0.004 "  euler=" 0.0 0.0 0.485">\-->

<!--                            <geom name="touch_4_1_6"   class="robot0:Tactile" friction="0.5 0.5 0.005" mesh="tactile_sphere1" pos="-0.0005 0 0" quat="0.707107 0 0.707107 0"/>-->
<!--                            <geom name="touch_4_1_6"   class="robot0:D_Contact" friction="0.5 0.5 0.005" mesh="tactile_sphere1" pos="-0.0005 0 0" quat="0.707107 0 0.707107 0"/>-->
<!--                            </body>-->

<!--                            <body name="touch_4_2_6" pos=" 0.005265 0.01463 0.004 "  euler=" 0.0 0.0 0.1777">\-->

<!--                            <geom name="touch_4_2_6"   class="robot0:Tactile" friction="0.5 0.5 0.005" mesh="tactile_sphere1" pos="-0.0005 0 0" quat="0.707107 0 0.707107 0"/>-->
<!--                            <geom name="touch_4_2_6"   class="robot0:D_Contact" friction="0.5 0.5 0.005" mesh="tactile_sphere1" pos="-0.0005 0 0" quat="0.707107 0 0.707107 0"/>-->
<!--                            </body>-->

<!--                            <body name="touch_4_3_6" pos=" 0.00581 0.01154 0.004"  euler=" 0.0 0.0 0.0">\-->

<!--                            <geom name="touch_4_3_6"   class="robot0:Tactile" friction="0.5 0.5 0.005" mesh="tactile_sphere1" pos="-0.0005 0 0" quat="0.707107 0 0.707107 0"/>-->
<!--                            <geom name="touch_4_3_6"   class="robot0:D_Contact" friction="0.5 0.5 0.005" mesh="tactile_sphere1" pos="-0.0005 0 0" quat="0.707107 0 0.707107 0"/>-->
<!--                            </body>-->

<!--                            <body name="touch_4_4_6" pos=" 0.00581 0.00846 0.004 "  euler=" 0.0 0.0 0.0">\-->

<!--                            <geom name="touch_4_4_6"   class="robot0:Tactile" friction="0.5 0.5 0.005" mesh="tactile_sphere1" pos="-0.0005 0 0" quat="0.707107 0 0.707107 0"/>-->
<!--                            <geom name="touch_4_4_6"   class="robot0:D_Contact" friction="0.5 0.5 0.005" mesh="tactile_sphere1" pos="-0.0005 0 0" quat="0.707107 0 0.707107 0"/>-->
<!--                            </body>-->

<!--                            <body name="touch_4_5_6" pos=" 0.005265 0.00537 0.004 "  euler=" 0.0 0.0 -0.1777">\-->

<!--                            <geom name="touch_4_5_6"   class="robot0:Tactile" friction="0.5 0.5 0.005" mesh="tactile_sphere1" pos="-0.0005 0 0" quat="0.707107 0 0.707107 0"/>-->
<!--                            <geom name="touch_4_5_6"   class="robot0:D_Contact" friction="0.5 0.5 0.005" mesh="tactile_sphere1" pos="-0.0005 0 0" quat="0.707107 0 0.707107 0"/>-->
<!--                            </body>-->

<!--                            <body name="touch_4_6_6" pos=" 0.00414 0.00248 0.004 "  euler=" 0.0 0.0 -0.485">\-->

<!--                            <geom name="touch_4_6_6"   class="robot0:Tactile" friction="0.5 0.5 0.005" mesh="tactile_sphere1" pos="-0.0005 0 0" quat="0.707107 0 0.707107 0"/>-->
<!--                            <geom name="touch_4_6_6"   class="robot0:D_Contact" friction="0.5 0.5 0.005" mesh="tactile_sphere1" pos="-0.0005 0 0" quat="0.707107 0 0.707107 0"/>-->
<!--                            </body>-->

<!--                        </body>-->

                        </body>

                        <body name="link_7.0" pos="0 0 0.0384">
                            <inertial pos="0 0 0.0169909" mass="0.0264" diaginertia="9.67371e-06 9.67371e-06 5.3186e-06" />
                            <joint name="joint_7.0" pos="0 0 0" axis="0 1 0" limited="true" range="-0.227 1.618" damping="1" frictionloss="12" stiffness="1" />
                            <geom  class="robot0:Finger" type="mesh" mesh="link_3.0" rgba="0.2 0.2 0.2 1" />
                            <geom  class="robot0:D_Contact" type="mesh" mesh="link_3.0" rgba="0.2 0.2 0.2 1" />

                            <!-- finger tip -->
                            <body name="link_7.0_tip" pos="0.002 0 0.0157">
                                <geom  class="robot0:Pad" pos="0 0 0" rgba="0.9 0.9 0.9 1" type="mesh" mesh="link_3.0_tip"  euler="0 0 0"/>
                                <geom  class="robot0:D_Contact" pos="0 0 0" rgba="0.9 0.9 0.9 1" type="mesh" mesh="link_3.0_tip"  euler="0 0 0"/>

                            </body>
                        </body>
                    </body>
                </body>
            </body>

            <!-- finger 3 -->
            <body name="link_8.0" pos="0 -0.0435 -0.001542" quat="0.999048 0.0436194 0 0">
                <inertial pos="0 0 0" quat="0.707107 0.707107 0 0" mass="0.0119" diaginertia="1.01667e-06 1.01667e-06 6.47677e-07" />
                <joint name="joint_4.0" pos="0 0 0" axis="0 0 1" limited="true" range="-0.47 0.47" damping="1" frictionloss="1" stiffness="1"/>
                <geom  class="robot0:Finger" type="mesh" mesh="link_0.0" rgba="0.2 0.2 0.2 1"/>
                <geom  class="robot0:D_Contact" type="mesh" mesh="link_0.0" rgba="0.2 0.2 0.2 1"/>

                <body name="link_9.0" pos="0 0 0.0164">
                    <inertial pos="0 0 0" quat="0.702596 0.559386 -0.178354 0.402039" mass="0.065" diaginertia="6.12799e-05 6.12799e-05 6.12799e-05" />
                    <joint name="joint_5.0" pos="0 0 0" axis="0 1 0" limited="true" range="-0.196 1.61" damping="3" frictionloss="5" />
                    <geom  class="robot0:Finger" type="mesh" mesh="link_1.0" rgba="0.2 0.2 0.2 1"/>
                    <geom  class="robot0:D_Contact" type="mesh" mesh="link_1.0" rgba="0.2 0.2 0.2 1"/>

                    <!-- tactile pad -->
                    <body name="link_9.0_middle" pos="0.01 -0.01 0.015" euler="0 0 0">
                        <inertial pos="0 0 0" quat="0.719796 0.528175 -0.157463 0.422055" mass="0.01" diaginertia="9.99999e-07 -9.92483e-07 9.92475e-07" />
                        <geom  class="robot0:Pad" pos="0 0 0"  type="mesh" mesh="link_middle" rgba="0.9 0.9 0.9 1" euler="0 0 0" />
                        <geom  class="robot0:D_Contact" pos="0 0 0"  type="mesh" mesh="link_middle" rgba="0.9 0.9 0.9 1" euler="0 0 0" />

                        <!--tactile sensor for link 9.0 -->
<!--                        <body name="link_9.0_tactile" pos="0.000 0 0">-->
<!--                        <body name="touch_8_1_1" pos=" 0.00414 0.01752 0.024 "  euler=" 0.0 0.0 0.485">\-->
<!--         -->
<!--                        <geom name="touch_8_1_1"   class="robot0:Tactile" friction="0.5 0.5 0.005" mesh="tactile_sphere1" pos="-0.0005 0 0" quat="0.707107 0 0.707107 0"/>-->
<!--                        <geom name="touch_8_1_1"   class="robot0:D_Contact" friction="0.5 0.5 0.005" mesh="tactile_sphere1" pos="-0.0005 0 0" quat="0.707107 0 0.707107 0"/>-->
<!--                        </body>-->

<!--                        <body name="touch_8_2_1" pos=" 0.005265 0.01463 0.024 "  euler=" 0.0 0.0 0.1777">\-->
<!--         -->
<!--                        <geom name="touch_8_2_1"   class="robot0:Tactile" friction="0.5 0.5 0.005" mesh="tactile_sphere1" pos="-0.0005 0 0" quat="0.707107 0 0.707107 0"/>-->
<!--                        <geom name="touch_8_2_1"   class="robot0:D_Contact" friction="0.5 0.5 0.005" mesh="tactile_sphere1" pos="-0.0005 0 0" quat="0.707107 0 0.707107 0"/>-->
<!--                        </body>-->

<!--                        <body name="touch_8_3_1" pos=" 0.00581 0.01154 0.024"  euler=" 0.0 0.0 0.0">\-->
<!--         -->
<!--                        <geom name="touch_8_3_1"   class="robot0:Tactile" friction="0.5 0.5 0.005" mesh="tactile_sphere1" pos="-0.0005 0 0" quat="0.707107 0 0.707107 0"/>-->
<!--                        <geom name="touch_8_3_1"   class="robot0:D_Contact" friction="0.5 0.5 0.005" mesh="tactile_sphere1" pos="-0.0005 0 0" quat="0.707107 0 0.707107 0"/>-->
<!--                        </body>-->

<!--                        <body name="touch_8_4_1" pos=" 0.00581 0.00846 0.024 "  euler=" 0.0 0.0 0.0">\-->
<!--         -->
<!--                        <geom name="touch_8_4_1"   class="robot0:Tactile" friction="0.5 0.5 0.005" mesh="tactile_sphere1" pos="-0.0005 0 0" quat="0.707107 0 0.707107 0"/>-->
<!--                        <geom name="touch_8_4_1"   class="robot0:D_Contact" friction="0.5 0.5 0.005" mesh="tactile_sphere1" pos="-0.0005 0 0" quat="0.707107 0 0.707107 0"/>-->
<!--                        </body>-->

<!--                        <body name="touch_8_5_1" pos=" 0.005265 0.00537 0.024 "  euler=" 0.0 0.0 -0.1777">\-->
<!--         -->
<!--                        <geom name="touch_8_5_1"   class="robot0:Tactile" friction="0.5 0.5 0.005" mesh="tactile_sphere1" pos="-0.0005 0 0" quat="0.707107 0 0.707107 0"/>-->
<!--                        <geom name="touch_8_5_1"   class="robot0:D_Contact" friction="0.5 0.5 0.005" mesh="tactile_sphere1" pos="-0.0005 0 0" quat="0.707107 0 0.707107 0"/>-->
<!--                        </body>-->


<!--                        <body name="touch_8_6_1" pos=" 0.00414 0.00248 0.024 "  euler=" 0.0 0.0 -0.485">\-->
<!--         -->
<!--                        <geom name="touch_8_6_1"   class="robot0:Tactile" friction="0.5 0.5 0.005" mesh="tactile_sphere1" pos="-0.0005 0 0" quat="0.707107 0 0.707107 0"/>-->
<!--                        <geom name="touch_8_6_1"   class="robot0:D_Contact" friction="0.5 0.5 0.005" mesh="tactile_sphere1" pos="-0.0005 0 0" quat="0.707107 0 0.707107 0"/>-->
<!--                        </body>-->

<!--                        <body name="touch_8_1_2" pos=" 0.00414 0.01752 0.02 "  euler=" 0.0 0.0 0.485">\-->
<!--         -->
<!--                        <geom name="touch_8_1_2"   class="robot0:Tactile" friction="0.5 0.5 0.005" mesh="tactile_sphere1" pos="-0.0005 0 0" quat="0.707107 0 0.707107 0"/>-->
<!--                        <geom name="touch_8_1_2"   class="robot0:D_Contact" friction="0.5 0.5 0.005" mesh="tactile_sphere1" pos="-0.0005 0 0" quat="0.707107 0 0.707107 0"/>-->
<!--                        </body>-->

<!--                        <body name="touch_8_2_2" pos=" 0.005265 0.01463 0.02 "  euler=" 0.0 0.0 0.1777">\-->
<!--         -->
<!--                        <geom name="touch_8_2_2"   class="robot0:Tactile" friction="0.5 0.5 0.005" mesh="tactile_sphere1" pos="-0.0005 0 0" quat="0.707107 0 0.707107 0"/>-->
<!--                        <geom name="touch_8_2_2"   class="robot0:D_Contact" friction="0.5 0.5 0.005" mesh="tactile_sphere1" pos="-0.0005 0 0" quat="0.707107 0 0.707107 0"/>-->
<!--                        </body>-->

<!--                        <body name="touch_8_3_2" pos=" 0.00581 0.01154 0.02"  euler=" 0.0 0.0 0.0">\-->
<!--         -->
<!--                        <geom name="touch_8_3_2"   class="robot0:Tactile" friction="0.5 0.5 0.005" mesh="tactile_sphere1" pos="-0.0005 0 0" quat="0.707107 0 0.707107 0"/>-->
<!--                        <geom name="touch_8_3_2"   class="robot0:D_Contact" friction="0.5 0.5 0.005" mesh="tactile_sphere1" pos="-0.0005 0 0" quat="0.707107 0 0.707107 0"/>-->
<!--                        </body>-->

<!--                        <body name="touch_8_4_2" pos=" 0.00581 0.00846 0.02 "  euler=" 0.0 0.0 0.0">\-->
<!--         -->
<!--                        <geom name="touch_8_4_2"   class="robot0:Tactile" friction="0.5 0.5 0.005" mesh="tactile_sphere1" pos="-0.0005 0 0" quat="0.707107 0 0.707107 0"/>-->
<!--                        <geom name="touch_8_4_2"   class="robot0:D_Contact" friction="0.5 0.5 0.005" mesh="tactile_sphere1" pos="-0.0005 0 0" quat="0.707107 0 0.707107 0"/>-->
<!--                        </body>-->

<!--                        <body name="touch_8_5_2" pos=" 0.005265 0.00537 0.02 "  euler=" 0.0 0.0 -0.1777">\-->
<!--         -->
<!--                        <geom name="touch_8_5_2"   class="robot0:Tactile" friction="0.5 0.5 0.005" mesh="tactile_sphere1" pos="-0.0005 0 0" quat="0.707107 0 0.707107 0"/>-->
<!--                        <geom name="touch_8_5_2"   class="robot0:D_Contact" friction="0.5 0.5 0.005" mesh="tactile_sphere1" pos="-0.0005 0 0" quat="0.707107 0 0.707107 0"/>-->
<!--                        </body>-->

<!--                        <body name="touch_8_6_2" pos=" 0.00414 0.00248 0.02 "  euler=" 0.0 0.0 -0.485">\-->
<!--         -->
<!--                        <geom name="touch_8_6_2"   class="robot0:Tactile" friction="0.5 0.5 0.005" mesh="tactile_sphere1" pos="-0.0005 0 0" quat="0.707107 0 0.707107 0"/>-->
<!--                        <geom name="touch_8_6_2"   class="robot0:D_Contact" friction="0.5 0.5 0.005" mesh="tactile_sphere1" pos="-0.0005 0 0" quat="0.707107 0 0.707107 0"/>-->
<!--                        </body>-->

<!--                        <body name="touch_8_1_3" pos=" 0.00414 0.01752 0.016 "  euler=" 0.0 0.0 0.485">\-->
<!--         -->
<!--                        <geom name="touch_8_1_3"   class="robot0:Tactile" friction="0.5 0.5 0.005" mesh="tactile_sphere1" pos="-0.0005 0 0" quat="0.707107 0 0.707107 0"/>-->
<!--                        <geom name="touch_8_1_3"   class="robot0:D_Contact" friction="0.5 0.5 0.005" mesh="tactile_sphere1" pos="-0.0005 0 0" quat="0.707107 0 0.707107 0"/>-->
<!--                        </body>-->

<!--                        <body name="touch_8_2_3" pos=" 0.005265 0.01463 0.016 "  euler=" 0.0 0.0 0.1777">\-->
<!--         -->
<!--                        <geom name="touch_8_2_3"   class="robot0:Tactile" friction="0.5 0.5 0.005" mesh="tactile_sphere1" pos="-0.0005 0 0" quat="0.707107 0 0.707107 0"/>-->
<!--                        <geom name="touch_8_2_3"   class="robot0:D_Contact" friction="0.5 0.5 0.005" mesh="tactile_sphere1" pos="-0.0005 0 0" quat="0.707107 0 0.707107 0"/>-->
<!--                        </body>-->

<!--                        <body name="touch_8_3_3" pos=" 0.00581 0.01154 0.016"  euler=" 0.0 0.0 0.0">\-->
<!--         -->
<!--                        <geom name="touch_8_3_3"   class="robot0:Tactile" friction="0.5 0.5 0.005" mesh="tactile_sphere1" pos="-0.0005 0 0" quat="0.707107 0 0.707107 0"/>-->
<!--                        <geom name="touch_8_3_3"   class="robot0:D_Contact" friction="0.5 0.5 0.005" mesh="tactile_sphere1" pos="-0.0005 0 0" quat="0.707107 0 0.707107 0"/>-->
<!--                        </body>-->

<!--                        <body name="touch_8_4_3" pos=" 0.00581 0.00846 0.016 "  euler=" 0.0 0.0 0.0">\-->
<!--         -->
<!--                        <geom name="touch_8_4_3"   class="robot0:Tactile" friction="0.5 0.5 0.005" mesh="tactile_sphere1" pos="-0.0005 0 0" quat="0.707107 0 0.707107 0"/>-->
<!--                        <geom name="touch_8_4_3"   class="robot0:D_Contact" friction="0.5 0.5 0.005" mesh="tactile_sphere1" pos="-0.0005 0 0" quat="0.707107 0 0.707107 0"/>-->
<!--                        </body>-->

<!--                        <body name="touch_8_5_3" pos=" 0.005265 0.00537 0.016 "  euler=" 0.0 0.0 -0.1777">\-->
<!--         -->
<!--                        <geom name="touch_8_5_3"   class="robot0:Tactile" friction="0.5 0.5 0.005" mesh="tactile_sphere1" pos="-0.0005 0 0" quat="0.707107 0 0.707107 0"/>-->
<!--                        <geom name="touch_8_5_3"   class="robot0:D_Contact" friction="0.5 0.5 0.005" mesh="tactile_sphere1" pos="-0.0005 0 0" quat="0.707107 0 0.707107 0"/>-->
<!--                        </body>-->

<!--                        <body name="touch_8_6_3" pos=" 0.00414 0.00248 0.016 "  euler=" 0.0 0.0 -0.485">\-->
<!--         -->
<!--                        <geom name="touch_8_6_3"   class="robot0:Tactile" friction="0.5 0.5 0.005" mesh="tactile_sphere1" pos="-0.0005 0 0" quat="0.707107 0 0.707107 0"/>-->
<!--                        <geom name="touch_8_6_3"   class="robot0:D_Contact" friction="0.5 0.5 0.005" mesh="tactile_sphere1" pos="-0.0005 0 0" quat="0.707107 0 0.707107 0"/>-->
<!--                        </body>-->


<!--                        <body name="touch_8_1_4" pos=" 0.00414 0.01752 0.012 "  euler=" 0.0 0.0 0.485">\-->
<!--         -->
<!--                        <geom name="touch_8_1_4"   class="robot0:Tactile" friction="0.5 0.5 0.005" mesh="tactile_sphere1" pos="-0.0005 0 0" quat="0.707107 0 0.707107 0"/>-->
<!--                        <geom name="touch_8_1_4"   class="robot0:D_Contact" friction="0.5 0.5 0.005" mesh="tactile_sphere1" pos="-0.0005 0 0" quat="0.707107 0 0.707107 0"/>-->
<!--                        </body>-->

<!--                        <body name="touch_8_2_4" pos=" 0.005265 0.01463 0.012 "  euler=" 0.0 0.0 0.1777">\-->
<!--         -->
<!--                        <geom name="touch_8_2_4"   class="robot0:Tactile" friction="0.5 0.5 0.005" mesh="tactile_sphere1" pos="-0.0005 0 0" quat="0.707107 0 0.707107 0"/>-->
<!--                        <geom name="touch_8_2_4"   class="robot0:D_Contact" friction="0.5 0.5 0.005" mesh="tactile_sphere1" pos="-0.0005 0 0" quat="0.707107 0 0.707107 0"/>-->
<!--                        </body>-->

<!--                        <body name="touch_8_3_4" pos=" 0.00581 0.01154 0.012"  euler=" 0.0 0.0 0.0">\-->
<!--         -->
<!--                        <geom name="touch_8_3_4"   class="robot0:Tactile" friction="0.5 0.5 0.005" mesh="tactile_sphere1" pos="-0.0005 0 0" quat="0.707107 0 0.707107 0"/>-->
<!--                        <geom name="touch_8_3_4"   class="robot0:D_Contact" friction="0.5 0.5 0.005" mesh="tactile_sphere1" pos="-0.0005 0 0" quat="0.707107 0 0.707107 0"/>-->
<!--                        </body>-->

<!--                        <body name="touch_8_4_4" pos=" 0.00581 0.00846 0.012 "  euler=" 0.0 0.0 0.0">\-->
<!--         -->
<!--                        <geom name="touch_8_4_4"   class="robot0:Tactile" friction="0.5 0.5 0.005" mesh="tactile_sphere1" pos="-0.0005 0 0" quat="0.707107 0 0.707107 0"/>-->
<!--                        <geom name="touch_8_4_4"   class="robot0:D_Contact" friction="0.5 0.5 0.005" mesh="tactile_sphere1" pos="-0.0005 0 0" quat="0.707107 0 0.707107 0"/>-->
<!--                        </body>-->

<!--                        <body name="touch_8_5_4" pos=" 0.005265 0.00537 0.012 "  euler=" 0.0 0.0 -0.1777">\-->
<!--         -->
<!--                        <geom name="touch_8_5_4"   class="robot0:Tactile" friction="0.5 0.5 0.005" mesh="tactile_sphere1" pos="-0.0005 0 0" quat="0.707107 0 0.707107 0"/>-->
<!--                        <geom name="touch_8_5_4"   class="robot0:D_Contact" friction="0.5 0.5 0.005" mesh="tactile_sphere1" pos="-0.0005 0 0" quat="0.707107 0 0.707107 0"/>-->
<!--                        </body>-->

<!--                        <body name="touch_8_6_4" pos=" 0.00414 0.00248 0.012 "  euler=" 0.0 0.0 -0.485">\-->
<!--         -->
<!--                        <geom name="touch_8_6_4"   class="robot0:Tactile" friction="0.5 0.5 0.005" mesh="tactile_sphere1" pos="-0.0005 0 0" quat="0.707107 0 0.707107 0"/>-->
<!--                        <geom name="touch_8_6_4"   class="robot0:D_Contact" friction="0.5 0.5 0.005" mesh="tactile_sphere1" pos="-0.0005 0 0" quat="0.707107 0 0.707107 0"/>-->
<!--                        </body>-->


<!--                        <body name="touch_8_1_5" pos=" 0.00414 0.01752 0.008 "  euler=" 0.0 0.0 0.485">\-->
<!--         -->
<!--                        <geom name="touch_8_1_5"   class="robot0:Tactile" friction="0.5 0.5 0.005" mesh="tactile_sphere1" pos="-0.0005 0 0" quat="0.707107 0 0.707107 0"/>-->
<!--                        <geom name="touch_8_1_5"   class="robot0:D_Contact" friction="0.5 0.5 0.005" mesh="tactile_sphere1" pos="-0.0005 0 0" quat="0.707107 0 0.707107 0"/>-->
<!--                        </body>-->

<!--                        <body name="touch_8_2_5" pos=" 0.005265 0.01463 0.008 "  euler=" 0.0 0.0 0.1777">\-->
<!--         -->
<!--                        <geom name="touch_8_2_5"   class="robot0:Tactile" friction="0.5 0.5 0.005" mesh="tactile_sphere1" pos="-0.0005 0 0" quat="0.707107 0 0.707107 0"/>-->
<!--                        <geom name="touch_8_2_5"   class="robot0:D_Contact" friction="0.5 0.5 0.005" mesh="tactile_sphere1" pos="-0.0005 0 0" quat="0.707107 0 0.707107 0"/>-->
<!--                        </body>-->

<!--                        <body name="touch_8_3_5" pos=" 0.00581 0.01154 0.008"  euler=" 0.0 0.0 0.0">\-->
<!--         -->
<!--                        <geom name="touch_8_3_5"   class="robot0:Tactile" friction="0.5 0.5 0.005" mesh="tactile_sphere1" pos="-0.0005 0 0" quat="0.707107 0 0.707107 0"/>-->
<!--                        <geom name="touch_8_3_5"   class="robot0:D_Contact" friction="0.5 0.5 0.005" mesh="tactile_sphere1" pos="-0.0005 0 0" quat="0.707107 0 0.707107 0"/>-->
<!--                        </body>-->

<!--                        <body name="touch_8_4_5" pos=" 0.00581 0.00846 0.008 "  euler=" 0.0 0.0 0.0">\-->
<!--         -->
<!--                        <geom name="touch_8_4_5"   class="robot0:Tactile" friction="0.5 0.5 0.005" mesh="tactile_sphere1" pos="-0.0005 0 0" quat="0.707107 0 0.707107 0"/>-->
<!--                        <geom name="touch_8_4_5"   class="robot0:D_Contact" friction="0.5 0.5 0.005" mesh="tactile_sphere1" pos="-0.0005 0 0" quat="0.707107 0 0.707107 0"/>-->
<!--                        </body>-->

<!--                        <body name="touch_8_5_5" pos=" 0.005265 0.00537 0.008 "  euler=" 0.0 0.0 -0.1777">\-->
<!--         -->
<!--                        <geom name="touch_8_5_5"   class="robot0:Tactile" friction="0.5 0.5 0.005" mesh="tactile_sphere1" pos="-0.0005 0 0" quat="0.707107 0 0.707107 0"/>-->
<!--                        <geom name="touch_8_5_5"   class="robot0:D_Contact" friction="0.5 0.5 0.005" mesh="tactile_sphere1" pos="-0.0005 0 0" quat="0.707107 0 0.707107 0"/>-->
<!--                        </body>-->

<!--                        <body name="touch_8_6_5" pos=" 0.00414 0.00248 0.008 "  euler=" 0.0 0.0 -0.485">\-->
<!--         -->
<!--                        <geom name="touch_8_6_5"   class="robot0:Tactile" friction="0.5 0.5 0.005" mesh="tactile_sphere1" pos="-0.0005 0 0" quat="0.707107 0 0.707107 0"/>-->
<!--                        <geom name="touch_8_6_5"   class="robot0:D_Contact" friction="0.5 0.5 0.005" mesh="tactile_sphere1" pos="-0.0005 0 0" quat="0.707107 0 0.707107 0"/>-->
<!--                        </body>-->


<!--                        <body name="touch_8_1_6" pos=" 0.00414 0.01752 0.004 "  euler=" 0.0 0.0 0.485">\-->
<!--         -->
<!--                        <geom name="touch_8_1_6"   class="robot0:Tactile" friction="0.5 0.5 0.005" mesh="tactile_sphere1" pos="-0.0005 0 0" quat="0.707107 0 0.707107 0"/>-->
<!--                        <geom name="touch_8_1_6"   class="robot0:D_Contact" friction="0.5 0.5 0.005" mesh="tactile_sphere1" pos="-0.0005 0 0" quat="0.707107 0 0.707107 0"/>-->
<!--                        </body>-->

<!--                        <body name="touch_8_2_6" pos=" 0.005265 0.01463 0.004 "  euler=" 0.0 0.0 0.1777">\-->
<!--         -->
<!--                        <geom name="touch_8_2_6"   class="robot0:Tactile" friction="0.5 0.5 0.005" mesh="tactile_sphere1" pos="-0.0005 0 0" quat="0.707107 0 0.707107 0"/>-->
<!--                        <geom name="touch_8_2_6"   class="robot0:D_Contact" friction="0.5 0.5 0.005" mesh="tactile_sphere1" pos="-0.0005 0 0" quat="0.707107 0 0.707107 0"/>-->
<!--                        </body>-->

<!--                        <body name="touch_8_3_6" pos=" 0.00581 0.01154 0.004"  euler=" 0.0 0.0 0.0">\-->
<!--         -->
<!--                        <geom name="touch_8_3_6"   class="robot0:Tactile" friction="0.5 0.5 0.005" mesh="tactile_sphere1" pos="-0.0005 0 0" quat="0.707107 0 0.707107 0"/>-->
<!--                        <geom name="touch_8_3_6"   class="robot0:D_Contact" friction="0.5 0.5 0.005" mesh="tactile_sphere1" pos="-0.0005 0 0" quat="0.707107 0 0.707107 0"/>-->
<!--                        </body>-->

<!--                        <body name="touch_8_4_6" pos=" 0.00581 0.00846 0.004 "  euler=" 0.0 0.0 0.0">\-->
<!--         -->
<!--                        <geom name="touch_8_4_6"   class="robot0:Tactile" friction="0.5 0.5 0.005" mesh="tactile_sphere1" pos="-0.0005 0 0" quat="0.707107 0 0.707107 0"/>-->
<!--                        <geom name="touch_8_4_6"   class="robot0:D_Contact" friction="0.5 0.5 0.005" mesh="tactile_sphere1" pos="-0.0005 0 0" quat="0.707107 0 0.707107 0"/>-->
<!--                        </body>-->

<!--                        <body name="touch_8_5_6" pos=" 0.005265 0.00537 0.004 "  euler=" 0.0 0.0 -0.1777">\-->
<!--         -->
<!--                        <geom name="touch_8_5_6"   class="robot0:Tactile" friction="0.5 0.5 0.005" mesh="tactile_sphere1" pos="-0.0005 0 0" quat="0.707107 0 0.707107 0"/>-->
<!--                        <geom name="touch_8_5_6"   class="robot0:D_Contact" friction="0.5 0.5 0.005" mesh="tactile_sphere1" pos="-0.0005 0 0" quat="0.707107 0 0.707107 0"/>-->
<!--                        </body>-->

<!--                        <body name="touch_8_6_6" pos=" 0.00414 0.00248 0.004 "  euler=" 0.0 0.0 -0.485">\-->
<!--         -->
<!--                        <geom name="touch_8_6_6"   class="robot0:Tactile" friction="0.5 0.5 0.005" mesh="tactile_sphere1" pos="-0.0005 0 0" quat="0.707107 0 0.707107 0"/>-->
<!--                        <geom name="touch_8_6_6"   class="robot0:D_Contact" friction="0.5 0.5 0.005" mesh="tactile_sphere1" pos="-0.0005 0 0" quat="0.707107 0 0.707107 0"/>-->
<!--                        </body>-->

<!--                    </body>-->

                    </body>

                    <body name="link_10.0" pos="0 0 0.054">
                        <inertial pos="0 0 0" quat="0.719796 0.528175 -0.157463 0.422055" mass="0.0355" diaginertia="2.20969e-05 2.20969e-05 2.20969e-05" />
                        <joint name="joint_6.0" pos="0 0 0" axis="0 1 0" limited="true" range="-0.174 1.709" damping="1" frictionloss="1" stiffness="1" />
                        <geom  class="robot0:Finger" type="mesh" mesh="link_2.0" rgba="0.2 0.2 0.2 1"/>
                        <geom  class="robot0:D_Contact" type="mesh" mesh="link_2.0" rgba="0.2 0.2 0.2 1"/>

                        <!-- tactile pad -->
                        <body name="link_10.0_middle" pos="0.01 -0.01 0.015" euler="0 0 0">
                            <inertial pos="0 0 0" quat="0.719796 0.528175 -0.157463 0.422055" mass="0.01" diaginertia="9.99999e-07 -9.92483e-07 9.92475e-07" />
                            <geom  class="robot0:Pad" pos="0 0 0"  type="mesh" mesh="link_middle" rgba="0.9 0.9 0.9 1" euler="0 0 0" />
                            <geom  class="robot0:D_Contact" pos="0 0 0"  type="mesh" mesh="link_middle" rgba="0.9 0.9 0.9 1" euler="0 0 0" />

                            <!--tactile sensor for link 10.0 -->
<!--                            <body name="link_10.0_tactile" pos="0.000 0 0">-->
<!--                            <body name="touch_7_1_1" pos=" 0.00414 0.01752 0.024 "  euler=" 0.0 0.0 0.485">\-->
<!--             -->
<!--                            <geom name="touch_7_1_1"   class="robot0:Tactile" friction="0.5 0.5 0.005" mesh="tactile_sphere1" pos="-0.0005 0 0" quat="0.707107 0 0.707107 0"/>-->
<!--                            <geom name="touch_7_1_1"   class="robot0:D_Contact" friction="0.5 0.5 0.005" mesh="tactile_sphere1" pos="-0.0005 0 0" quat="0.707107 0 0.707107 0"/>-->
<!--                            </body>-->
<!--    -->
<!--                            <body name="touch_7_2_1" pos=" 0.005265 0.01463 0.024 "  euler=" 0.0 0.0 0.1777">\-->
<!--             -->
<!--                            <geom name="touch_7_2_1"   class="robot0:Tactile" friction="0.5 0.5 0.005" mesh="tactile_sphere1" pos="-0.0005 0 0" quat="0.707107 0 0.707107 0"/>-->
<!--                            <geom name="touch_7_2_1"   class="robot0:D_Contact" friction="0.5 0.5 0.005" mesh="tactile_sphere1" pos="-0.0005 0 0" quat="0.707107 0 0.707107 0"/>-->
<!--                            </body>-->
<!--    -->
<!--                            <body name="touch_7_3_1" pos=" 0.00581 0.01154 0.024"  euler=" 0.0 0.0 0.0">\-->
<!--             -->
<!--                            <geom name="touch_7_3_1"   class="robot0:Tactile" friction="0.5 0.5 0.005" mesh="tactile_sphere1" pos="-0.0005 0 0" quat="0.707107 0 0.707107 0"/>-->
<!--                            <geom name="touch_7_3_1"   class="robot0:D_Contact" friction="0.5 0.5 0.005" mesh="tactile_sphere1" pos="-0.0005 0 0" quat="0.707107 0 0.707107 0"/>-->
<!--                            </body>-->
<!--    -->
<!--                            <body name="touch_7_4_1" pos=" 0.00581 0.00846 0.024 "  euler=" 0.0 0.0 0.0">\-->
<!--             -->
<!--                            <geom name="touch_7_4_1"   class="robot0:Tactile" friction="0.5 0.5 0.005" mesh="tactile_sphere1" pos="-0.0005 0 0" quat="0.707107 0 0.707107 0"/>-->
<!--                            <geom name="touch_7_4_1"   class="robot0:D_Contact" friction="0.5 0.5 0.005" mesh="tactile_sphere1" pos="-0.0005 0 0" quat="0.707107 0 0.707107 0"/>-->
<!--                            </body>-->
<!--    -->
<!--                            <body name="touch_7_5_1" pos=" 0.005265 0.00537 0.024 "  euler=" 0.0 0.0 -0.1777">\-->
<!--             -->
<!--                            <geom name="touch_7_5_1"   class="robot0:Tactile" friction="0.5 0.5 0.005" mesh="tactile_sphere1" pos="-0.0005 0 0" quat="0.707107 0 0.707107 0"/>-->
<!--                            <geom name="touch_7_5_1"   class="robot0:D_Contact" friction="0.5 0.5 0.005" mesh="tactile_sphere1" pos="-0.0005 0 0" quat="0.707107 0 0.707107 0"/>-->
<!--                            </body>-->
<!--    -->
<!--    -->
<!--                            <body name="touch_7_6_1" pos=" 0.00414 0.00248 0.024 "  euler=" 0.0 0.0 -0.485">\-->
<!--             -->
<!--                            <geom name="touch_7_6_1"   class="robot0:Tactile" friction="0.5 0.5 0.005" mesh="tactile_sphere1" pos="-0.0005 0 0" quat="0.707107 0 0.707107 0"/>-->
<!--                            <geom name="touch_7_6_1"   class="robot0:D_Contact" friction="0.5 0.5 0.005" mesh="tactile_sphere1" pos="-0.0005 0 0" quat="0.707107 0 0.707107 0"/>-->
<!--                            </body>-->
<!--    -->
<!--                            <body name="touch_7_1_2" pos=" 0.00414 0.01752 0.02 "  euler=" 0.0 0.0 0.485">\-->
<!--             -->
<!--                            <geom name="touch_7_1_2"   class="robot0:Tactile" friction="0.5 0.5 0.005" mesh="tactile_sphere1" pos="-0.0005 0 0" quat="0.707107 0 0.707107 0"/>-->
<!--                            <geom name="touch_7_1_2"   class="robot0:D_Contact" friction="0.5 0.5 0.005" mesh="tactile_sphere1" pos="-0.0005 0 0" quat="0.707107 0 0.707107 0"/>-->
<!--                            </body>-->
<!--    -->
<!--                            <body name="touch_7_2_2" pos=" 0.005265 0.01463 0.02 "  euler=" 0.0 0.0 0.1777">\-->
<!--             -->
<!--                            <geom name="touch_7_2_2"   class="robot0:Tactile" friction="0.5 0.5 0.005" mesh="tactile_sphere1" pos="-0.0005 0 0" quat="0.707107 0 0.707107 0"/>-->
<!--                            <geom name="touch_7_2_2"   class="robot0:D_Contact" friction="0.5 0.5 0.005" mesh="tactile_sphere1" pos="-0.0005 0 0" quat="0.707107 0 0.707107 0"/>-->
<!--                            </body>-->
<!--    -->
<!--                            <body name="touch_7_3_2" pos=" 0.00581 0.01154 0.02"  euler=" 0.0 0.0 0.0">\-->
<!--             -->
<!--                            <geom name="touch_7_3_2"   class="robot0:Tactile" friction="0.5 0.5 0.005" mesh="tactile_sphere1" pos="-0.0005 0 0" quat="0.707107 0 0.707107 0"/>-->
<!--                            <geom name="touch_7_3_2"   class="robot0:D_Contact" friction="0.5 0.5 0.005" mesh="tactile_sphere1" pos="-0.0005 0 0" quat="0.707107 0 0.707107 0"/>-->
<!--                            </body>-->
<!--    -->
<!--                            <body name="touch_7_4_2" pos=" 0.00581 0.00846 0.02 "  euler=" 0.0 0.0 0.0">\-->
<!--             -->
<!--                            <geom name="touch_7_4_2"   class="robot0:Tactile" friction="0.5 0.5 0.005" mesh="tactile_sphere1" pos="-0.0005 0 0" quat="0.707107 0 0.707107 0"/>-->
<!--                            <geom name="touch_7_4_2"   class="robot0:D_Contact" friction="0.5 0.5 0.005" mesh="tactile_sphere1" pos="-0.0005 0 0" quat="0.707107 0 0.707107 0"/>-->
<!--                            </body>-->
<!--    -->
<!--                            <body name="touch_7_5_2" pos=" 0.005265 0.00537 0.02 "  euler=" 0.0 0.0 -0.1777">\-->
<!--             -->
<!--                            <geom name="touch_7_5_2"   class="robot0:Tactile" friction="0.5 0.5 0.005" mesh="tactile_sphere1" pos="-0.0005 0 0" quat="0.707107 0 0.707107 0"/>-->
<!--                            <geom name="touch_7_5_2"   class="robot0:D_Contact" friction="0.5 0.5 0.005" mesh="tactile_sphere1" pos="-0.0005 0 0" quat="0.707107 0 0.707107 0"/>-->
<!--                            </body>-->
<!--    -->
<!--                            <body name="touch_7_6_2" pos=" 0.00414 0.00248 0.02 "  euler=" 0.0 0.0 -0.485">\-->
<!--             -->
<!--                            <geom name="touch_7_6_2"   class="robot0:Tactile" friction="0.5 0.5 0.005" mesh="tactile_sphere1" pos="-0.0005 0 0" quat="0.707107 0 0.707107 0"/>-->
<!--                            <geom name="touch_7_6_2"   class="robot0:D_Contact" friction="0.5 0.5 0.005" mesh="tactile_sphere1" pos="-0.0005 0 0" quat="0.707107 0 0.707107 0"/>-->
<!--                            </body>-->
<!--    -->
<!--                            <body name="touch_7_1_3" pos=" 0.00414 0.01752 0.016 "  euler=" 0.0 0.0 0.485">\-->
<!--             -->
<!--                            <geom name="touch_7_1_3"   class="robot0:Tactile" friction="0.5 0.5 0.005" mesh="tactile_sphere1" pos="-0.0005 0 0" quat="0.707107 0 0.707107 0"/>-->
<!--                            <geom name="touch_7_1_3"   class="robot0:D_Contact" friction="0.5 0.5 0.005" mesh="tactile_sphere1" pos="-0.0005 0 0" quat="0.707107 0 0.707107 0"/>-->
<!--                            </body>-->
<!--    -->
<!--                            <body name="touch_7_2_3" pos=" 0.005265 0.01463 0.016 "  euler=" 0.0 0.0 0.1777">\-->
<!--             -->
<!--                            <geom name="touch_7_2_3"   class="robot0:Tactile" friction="0.5 0.5 0.005" mesh="tactile_sphere1" pos="-0.0005 0 0" quat="0.707107 0 0.707107 0"/>-->
<!--                            <geom name="touch_7_2_3"   class="robot0:D_Contact" friction="0.5 0.5 0.005" mesh="tactile_sphere1" pos="-0.0005 0 0" quat="0.707107 0 0.707107 0"/>-->
<!--                            </body>-->
<!--    -->
<!--                            <body name="touch_7_3_3" pos=" 0.00581 0.01154 0.016"  euler=" 0.0 0.0 0.0">\-->
<!--             -->
<!--                            <geom name="touch_7_3_3"   class="robot0:Tactile" friction="0.5 0.5 0.005" mesh="tactile_sphere1" pos="-0.0005 0 0" quat="0.707107 0 0.707107 0"/>-->
<!--                            <geom name="touch_7_3_3"   class="robot0:D_Contact" friction="0.5 0.5 0.005" mesh="tactile_sphere1" pos="-0.0005 0 0" quat="0.707107 0 0.707107 0"/>-->
<!--                            </body>-->
<!--    -->
<!--                            <body name="touch_7_4_3" pos=" 0.00581 0.00846 0.016 "  euler=" 0.0 0.0 0.0">\-->
<!--             -->
<!--                            <geom name="touch_7_4_3"   class="robot0:Tactile" friction="0.5 0.5 0.005" mesh="tactile_sphere1" pos="-0.0005 0 0" quat="0.707107 0 0.707107 0"/>-->
<!--                            <geom name="touch_7_4_3"   class="robot0:D_Contact" friction="0.5 0.5 0.005" mesh="tactile_sphere1" pos="-0.0005 0 0" quat="0.707107 0 0.707107 0"/>-->
<!--                            </body>-->
<!--    -->
<!--                            <body name="touch_7_5_3" pos=" 0.005265 0.00537 0.016 "  euler=" 0.0 0.0 -0.1777">\-->
<!--             -->
<!--                            <geom name="touch_7_5_3"   class="robot0:Tactile" friction="0.5 0.5 0.005" mesh="tactile_sphere1" pos="-0.0005 0 0" quat="0.707107 0 0.707107 0"/>-->
<!--                            <geom name="touch_7_5_3"   class="robot0:D_Contact" friction="0.5 0.5 0.005" mesh="tactile_sphere1" pos="-0.0005 0 0" quat="0.707107 0 0.707107 0"/>-->
<!--                            </body>-->
<!--    -->
<!--                            <body name="touch_7_6_3" pos=" 0.00414 0.00248 0.016 "  euler=" 0.0 0.0 -0.485">\-->
<!--             -->
<!--                            <geom name="touch_7_6_3"   class="robot0:Tactile" friction="0.5 0.5 0.005" mesh="tactile_sphere1" pos="-0.0005 0 0" quat="0.707107 0 0.707107 0"/>-->
<!--                            <geom name="touch_7_6_3"   class="robot0:D_Contact" friction="0.5 0.5 0.005" mesh="tactile_sphere1" pos="-0.0005 0 0" quat="0.707107 0 0.707107 0"/>-->
<!--                            </body>-->
<!--    -->
<!--    -->
<!--                            <body name="touch_7_1_4" pos=" 0.00414 0.01752 0.012 "  euler=" 0.0 0.0 0.485">\-->
<!--             -->
<!--                            <geom name="touch_7_1_4"   class="robot0:Tactile" friction="0.5 0.5 0.005" mesh="tactile_sphere1" pos="-0.0005 0 0" quat="0.707107 0 0.707107 0"/>-->
<!--                            <geom name="touch_7_1_4"   class="robot0:D_Contact" friction="0.5 0.5 0.005" mesh="tactile_sphere1" pos="-0.0005 0 0" quat="0.707107 0 0.707107 0"/>-->
<!--                            </body>-->
<!--    -->
<!--                            <body name="touch_7_2_4" pos=" 0.005265 0.01463 0.012 "  euler=" 0.0 0.0 0.1777">\-->
<!--             -->
<!--                            <geom name="touch_7_2_4"   class="robot0:Tactile" friction="0.5 0.5 0.005" mesh="tactile_sphere1" pos="-0.0005 0 0" quat="0.707107 0 0.707107 0"/>-->
<!--                            <geom name="touch_7_2_4"   class="robot0:D_Contact" friction="0.5 0.5 0.005" mesh="tactile_sphere1" pos="-0.0005 0 0" quat="0.707107 0 0.707107 0"/>-->
<!--                            </body>-->
<!--    -->
<!--                            <body name="touch_7_3_4" pos=" 0.00581 0.01154 0.012"  euler=" 0.0 0.0 0.0">\-->
<!--             -->
<!--                            <geom name="touch_7_3_4"   class="robot0:Tactile" friction="0.5 0.5 0.005" mesh="tactile_sphere1" pos="-0.0005 0 0" quat="0.707107 0 0.707107 0"/>-->
<!--                            <geom name="touch_7_3_4"   class="robot0:D_Contact" friction="0.5 0.5 0.005" mesh="tactile_sphere1" pos="-0.0005 0 0" quat="0.707107 0 0.707107 0"/>-->
<!--                            </body>-->
<!--    -->
<!--                            <body name="touch_7_4_4" pos=" 0.00581 0.00846 0.012 "  euler=" 0.0 0.0 0.0">\-->
<!--             -->
<!--                            <geom name="touch_7_4_4"   class="robot0:Tactile" friction="0.5 0.5 0.005" mesh="tactile_sphere1" pos="-0.0005 0 0" quat="0.707107 0 0.707107 0"/>-->
<!--                            <geom name="touch_7_4_4"   class="robot0:D_Contact" friction="0.5 0.5 0.005" mesh="tactile_sphere1" pos="-0.0005 0 0" quat="0.707107 0 0.707107 0"/>-->
<!--                            </body>-->
<!--    -->
<!--                            <body name="touch_7_5_4" pos=" 0.005265 0.00537 0.012 "  euler=" 0.0 0.0 -0.1777">\-->
<!--             -->
<!--                            <geom name="touch_7_5_4"   class="robot0:Tactile" friction="0.5 0.5 0.005" mesh="tactile_sphere1" pos="-0.0005 0 0" quat="0.707107 0 0.707107 0"/>-->
<!--                            <geom name="touch_7_5_4"   class="robot0:D_Contact" friction="0.5 0.5 0.005" mesh="tactile_sphere1" pos="-0.0005 0 0" quat="0.707107 0 0.707107 0"/>-->
<!--                            </body>-->
<!--    -->
<!--                            <body name="touch_7_6_4" pos=" 0.00414 0.00248 0.012 "  euler=" 0.0 0.0 -0.485">\-->
<!--             -->
<!--                            <geom name="touch_7_6_4"   class="robot0:Tactile" friction="0.5 0.5 0.005" mesh="tactile_sphere1" pos="-0.0005 0 0" quat="0.707107 0 0.707107 0"/>-->
<!--                            <geom name="touch_7_6_4"   class="robot0:D_Contact" friction="0.5 0.5 0.005" mesh="tactile_sphere1" pos="-0.0005 0 0" quat="0.707107 0 0.707107 0"/>-->
<!--                            </body>-->
<!--    -->
<!--    -->
<!--                            <body name="touch_7_1_5" pos=" 0.00414 0.01752 0.008 "  euler=" 0.0 0.0 0.485">\-->
<!--             -->
<!--                            <geom name="touch_7_1_5"   class="robot0:Tactile" friction="0.5 0.5 0.005" mesh="tactile_sphere1" pos="-0.0005 0 0" quat="0.707107 0 0.707107 0"/>-->
<!--                            <geom name="touch_7_1_5"   class="robot0:D_Contact" friction="0.5 0.5 0.005" mesh="tactile_sphere1" pos="-0.0005 0 0" quat="0.707107 0 0.707107 0"/>-->
<!--                            </body>-->
<!--    -->
<!--                            <body name="touch_7_2_5" pos=" 0.005265 0.01463 0.008 "  euler=" 0.0 0.0 0.1777">\-->
<!--             -->
<!--                            <geom name="touch_7_2_5"   class="robot0:Tactile" friction="0.5 0.5 0.005" mesh="tactile_sphere1" pos="-0.0005 0 0" quat="0.707107 0 0.707107 0"/>-->
<!--                            <geom name="touch_7_2_5"   class="robot0:D_Contact" friction="0.5 0.5 0.005" mesh="tactile_sphere1" pos="-0.0005 0 0" quat="0.707107 0 0.707107 0"/>-->
<!--                            </body>-->
<!--    -->
<!--                            <body name="touch_7_3_5" pos=" 0.00581 0.01154 0.008"  euler=" 0.0 0.0 0.0">\-->
<!--             -->
<!--                            <geom name="touch_7_3_5"   class="robot0:Tactile" friction="0.5 0.5 0.005" mesh="tactile_sphere1" pos="-0.0005 0 0" quat="0.707107 0 0.707107 0"/>-->
<!--                            <geom name="touch_7_3_5"   class="robot0:D_Contact" friction="0.5 0.5 0.005" mesh="tactile_sphere1" pos="-0.0005 0 0" quat="0.707107 0 0.707107 0"/>-->
<!--                            </body>-->
<!--    -->
<!--                            <body name="touch_7_4_5" pos=" 0.00581 0.00846 0.008 "  euler=" 0.0 0.0 0.0">\-->
<!--             -->
<!--                            <geom name="touch_7_4_5"   class="robot0:Tactile" friction="0.5 0.5 0.005" mesh="tactile_sphere1" pos="-0.0005 0 0" quat="0.707107 0 0.707107 0"/>-->
<!--                            <geom name="touch_7_4_5"   class="robot0:D_Contact" friction="0.5 0.5 0.005" mesh="tactile_sphere1" pos="-0.0005 0 0" quat="0.707107 0 0.707107 0"/>-->
<!--                            </body>-->
<!--    -->
<!--                            <body name="touch_7_5_5" pos=" 0.005265 0.00537 0.008 "  euler=" 0.0 0.0 -0.1777">\-->
<!--             -->
<!--                            <geom name="touch_7_5_5"   class="robot0:Tactile" friction="0.5 0.5 0.005" mesh="tactile_sphere1" pos="-0.0005 0 0" quat="0.707107 0 0.707107 0"/>-->
<!--                            <geom name="touch_7_5_5"   class="robot0:D_Contact" friction="0.5 0.5 0.005" mesh="tactile_sphere1" pos="-0.0005 0 0" quat="0.707107 0 0.707107 0"/>-->
<!--                            </body>-->
<!--    -->
<!--                            <body name="touch_7_6_5" pos=" 0.00414 0.00248 0.008 "  euler=" 0.0 0.0 -0.485">\-->
<!--             -->
<!--                            <geom name="touch_7_6_5"   class="robot0:Tactile" friction="0.5 0.5 0.005" mesh="tactile_sphere1" pos="-0.0005 0 0" quat="0.707107 0 0.707107 0"/>-->
<!--                            <geom name="touch_7_6_5"   class="robot0:D_Contact" friction="0.5 0.5 0.005" mesh="tactile_sphere1" pos="-0.0005 0 0" quat="0.707107 0 0.707107 0"/>-->
<!--                            </body>-->
<!--    -->
<!--    -->
<!--                            <body name="touch_7_1_6" pos=" 0.00414 0.01752 0.004 "  euler=" 0.0 0.0 0.485">\-->
<!--             -->
<!--                            <geom name="touch_7_1_6"   class="robot0:Tactile" friction="0.5 0.5 0.005" mesh="tactile_sphere1" pos="-0.0005 0 0" quat="0.707107 0 0.707107 0"/>-->
<!--                            <geom name="touch_7_1_6"   class="robot0:D_Contact" friction="0.5 0.5 0.005" mesh="tactile_sphere1" pos="-0.0005 0 0" quat="0.707107 0 0.707107 0"/>-->
<!--                            </body>-->
<!--    -->
<!--                            <body name="touch_7_2_6" pos=" 0.005265 0.01463 0.004 "  euler=" 0.0 0.0 0.1777">\-->
<!--             -->
<!--                            <geom name="touch_7_2_6"   class="robot0:Tactile" friction="0.5 0.5 0.005" mesh="tactile_sphere1" pos="-0.0005 0 0" quat="0.707107 0 0.707107 0"/>-->
<!--                            <geom name="touch_7_2_6"   class="robot0:D_Contact" friction="0.5 0.5 0.005" mesh="tactile_sphere1" pos="-0.0005 0 0" quat="0.707107 0 0.707107 0"/>-->
<!--                            </body>-->
<!--    -->
<!--                            <body name="touch_7_3_6" pos=" 0.00581 0.01154 0.004"  euler=" 0.0 0.0 0.0">\-->
<!--             -->
<!--                            <geom name="touch_7_3_6"   class="robot0:Tactile" friction="0.5 0.5 0.005" mesh="tactile_sphere1" pos="-0.0005 0 0" quat="0.707107 0 0.707107 0"/>-->
<!--                            <geom name="touch_7_3_6"   class="robot0:D_Contact" friction="0.5 0.5 0.005" mesh="tactile_sphere1" pos="-0.0005 0 0" quat="0.707107 0 0.707107 0"/>-->
<!--                            </body>-->
<!--    -->
<!--                            <body name="touch_7_4_6" pos=" 0.00581 0.00846 0.004 "  euler=" 0.0 0.0 0.0">\-->
<!--             -->
<!--                            <geom name="touch_7_4_6"   class="robot0:Tactile" friction="0.5 0.5 0.005" mesh="tactile_sphere1" pos="-0.0005 0 0" quat="0.707107 0 0.707107 0"/>-->
<!--                            <geom name="touch_7_4_6"   class="robot0:D_Contact" friction="0.5 0.5 0.005" mesh="tactile_sphere1" pos="-0.0005 0 0" quat="0.707107 0 0.707107 0"/>-->
<!--                            </body>-->
<!--    -->
<!--                            <body name="touch_7_5_6" pos=" 0.005265 0.00537 0.004 "  euler=" 0.0 0.0 -0.1777">\-->
<!--             -->
<!--                            <geom name="touch_7_5_6"   class="robot0:Tactile" friction="0.5 0.5 0.005" mesh="tactile_sphere1" pos="-0.0005 0 0" quat="0.707107 0 0.707107 0"/>-->
<!--                            <geom name="touch_7_5_6"   class="robot0:D_Contact" friction="0.5 0.5 0.005" mesh="tactile_sphere1" pos="-0.0005 0 0" quat="0.707107 0 0.707107 0"/>-->
<!--                            </body>-->
<!--    -->
<!--                            <body name="touch_7_6_6" pos=" 0.00414 0.00248 0.004 "  euler=" 0.0 0.0 -0.485">\-->
<!--             -->
<!--                            <geom name="touch_7_6_6"   class="robot0:Tactile" friction="0.5 0.5 0.005" mesh="tactile_sphere1" pos="-0.0005 0 0" quat="0.707107 0 0.707107 0"/>-->
<!--                            <geom name="touch_7_6_6"   class="robot0:D_Contact" friction="0.5 0.5 0.005" mesh="tactile_sphere1" pos="-0.0005 0 0" quat="0.707107 0 0.707107 0"/>-->
<!--                            </body>-->
<!--    -->
<!--                        </body>-->

                        </body>

                        <body name="link_11.0" pos="0 0 0.0384">
                            <inertial pos="0 0 0.0169909" mass="0.0264" diaginertia="9.67371e-06 9.67371e-06 5.3186e-06" />
                            <joint name="joint_7.0" pos="0 0 0" axis="0 1 0" limited="true" range="-0.227 1.618" damping="1" frictionloss="12" stiffness="1" />
                            <geom size="0.0098 0.01375 0.01335" pos="0 0 0.01335" type="box" rgba="0.2 0.2 0.2 0"/>
                            <geom  class="robot0:Finger" type="mesh" mesh="link_3.0" rgba="0.2 0.2 0.2 1"/>
                            <geom  class="robot0:D_Contact" type="mesh" mesh="link_3.0" rgba="0.2 0.2 0.2 1"/>

                            <!-- finger tip -->
                            <body name="link_11.0_tip" pos="0.002 0 0.0157">
                                <geom  class="robot0:Pad" pos="0 0 0" rgba="0.9 0.9 0.9 1" type="mesh" mesh="link_3.0_tip"  euler="0 0 0"/>
                                <geom  class="robot0:D_Contact" pos="0 0 0" rgba="0.9 0.9 0.9 1" type="mesh" mesh="link_3.0_tip"  euler="0 0 0"/>
                            </body>
                        </body>
                    </body>
                </body>
            </body>

            <!-- finger 4 -->
            <body name="link_12.0" pos="-0.0182 0.019333 -0.045987" quat="0.477714 -0.521334 -0.521334 -0.477714">
                    <inertial pos="0 0 0" quat="0.692635 0.569362 -0.07143 0.437013" mass="0.0176" diaginertia="1.73852e-05 1.73852e-05 1.73852e-05" />
                    <joint name="joint_12.0" pos="0 0 0" axis="-1 0 0" limited="true" range="0.263 1.396" damping="3" frictionloss="10" />
                    <geom class="robot0:Finger" type="mesh" mesh="link_12.0" rgba="0.2 0.2 0.2 1" />
                    <geom class="robot0:D_Contact" type="mesh" mesh="link_12.0" rgba="0.2 0.2 0.2 1" />

                    <body name="link_13.0" pos="-0.027 0.005 0.0399">
                        <inertial pos="0 0 0" quat="-0.0269589 0.880876 0.334036 0.334292" mass="0.0119" diaginertia="4.33621e-06 4.33621e-06 4.33621e-06" />
                        <joint name="joint_13.0" pos="0 0 0" axis="0 0 1" limited="true" range="-0.105 1.163" damping="3" frictionloss="5" />
                        <geom class="robot0:Finger" type="mesh" mesh="link_13.0" rgba="0.2 0.2 0.2 1"/>
                        <geom class="robot0:D_Contact" type="mesh" mesh="link_13.0" rgba="0.2 0.2 0.2 1"/>

                        <body name="link_14.0" pos="0 0 0.0177">
                            <inertial pos="0 0 0" quat="0.70472 0.55555 -0.174905 0.405146" mass="0.038" diaginertia="3.35111e-05 3.35111e-05 3.35111e-05" />
                            <joint name="joint_14.0" pos="0 0 0" axis="0 1 0" limited="true" range="-0.189 1.644" damping="3" frictionloss="10" />
                            <geom class="robot0:Finger" type="mesh" mesh="link_14.0" rgba="0.2 0.2 0.2 1" />
                            <geom class="robot0:D_Contact" type="mesh" mesh="link_14.0" rgba="0.2 0.2 0.2 1" />

                            <body name="link_15.0" pos="0 0 0.0514">
                                <inertial pos="0 0 0.0127813" quat="0.707107 0 0 0.707107" mass="0.0556" diaginertia="4.88098e-05 4.88098e-05 2.78326e-05" />
                                <joint name="joint_15.0" pos="0 0 0" axis="0 1 0" limited="true" range="-0.162 1.719" damping="3" frictionloss="12" />
                                <geom class="robot0:Finger" type="mesh" mesh="link_15.0" rgba="0.2 0.2 0.2 1"/>
                                <geom class="robot0:D_Contact" type="mesh" mesh="link_15.0" rgba="0.2 0.2 0.2 1"/>

                                <!-- tactile pad -->
                                <body name="link_15.0_middle" pos="0.01 -0.01 0.0" euler="0 0 0">
                                    <inertial pos="0 0 0" quat="0.719796 0.528175 -0.157463 0.422055" mass="0.01" diaginertia="9.99999e-07 -9.92483e-07 9.92475e-07" />
                                    <geom class="robot0:Pad" pos="0 0 0"  type="mesh" mesh="link_middle" rgba="0.9 0.9 0.9 1" euler="0 0 0" />
                                    <geom class="robot0:D_Contact" pos="0 0 0"  type="mesh" mesh="link_middle" rgba="0.9 0.9 0.9 1" euler="0 0 0" />

                                    <!--tactile sensor for link 10.0 -->
<!--                                    <body name="link_10.0_tactile" pos="0.000 0 0">-->
<!--                                    <body name="touch_10_1_1" pos=" 0.00414 0.01752 0.024 "  euler=" 0.0 0.0 0.485">\-->
<!--                     -->
<!--                                    <geom name="touch_10_1_1"   class="robot0:Tactile" friction="0.5 0.5 0.005" mesh="tactile_sphere1" pos="-0.0005 0 0" quat="0.707107 0 0.707107 0"/>-->
<!--                                    <geom name="touch_10_1_1"   class="robot0:D_Contact" friction="0.5 0.5 0.005" mesh="tactile_sphere1" pos="-0.0005 0 0" quat="0.707107 0 0.707107 0"/>-->
<!--                                    </body>-->
<!--            -->
<!--                                    <body name="touch_10_2_1" pos=" 0.005265 0.01463 0.024 "  euler=" 0.0 0.0 0.1777">\-->
<!--                     -->
<!--                                    <geom name="touch_10_2_1"   class="robot0:Tactile" friction="0.5 0.5 0.005" mesh="tactile_sphere1" pos="-0.0005 0 0" quat="0.707107 0 0.707107 0"/>-->
<!--                                    <geom name="touch_10_2_1"   class="robot0:D_Contact" friction="0.5 0.5 0.005" mesh="tactile_sphere1" pos="-0.0005 0 0" quat="0.707107 0 0.707107 0"/>-->
<!--                                    </body>-->
<!--            -->
<!--                                    <body name="touch_10_3_1" pos=" 0.00581 0.01154 0.024"  euler=" 0.0 0.0 0.0">\-->
<!--                     -->
<!--                                    <geom name="touch_10_3_1"   class="robot0:Tactile" friction="0.5 0.5 0.005" mesh="tactile_sphere1" pos="-0.0005 0 0" quat="0.707107 0 0.707107 0"/>-->
<!--                                    <geom name="touch_10_3_1"   class="robot0:D_Contact" friction="0.5 0.5 0.005" mesh="tactile_sphere1" pos="-0.0005 0 0" quat="0.707107 0 0.707107 0"/>-->
<!--                                    </body>-->
<!--            -->
<!--                                    <body name="touch_10_4_1" pos=" 0.00581 0.00846 0.024 "  euler=" 0.0 0.0 0.0">\-->
<!--                     -->
<!--                                    <geom name="touch_10_4_1"   class="robot0:Tactile" friction="0.5 0.5 0.005" mesh="tactile_sphere1" pos="-0.0005 0 0" quat="0.707107 0 0.707107 0"/>-->
<!--                                    <geom name="touch_10_4_1"   class="robot0:D_Contact" friction="0.5 0.5 0.005" mesh="tactile_sphere1" pos="-0.0005 0 0" quat="0.707107 0 0.707107 0"/>-->
<!--                                    </body>-->
<!--            -->
<!--                                    <body name="touch_10_5_1" pos=" 0.005265 0.00537 0.024 "  euler=" 0.0 0.0 -0.1777">\-->
<!--                     -->
<!--                                    <geom name="touch_10_5_1"   class="robot0:Tactile" friction="0.5 0.5 0.005" mesh="tactile_sphere1" pos="-0.0005 0 0" quat="0.707107 0 0.707107 0"/>-->
<!--                                    <geom name="touch_10_5_1"   class="robot0:D_Contact" friction="0.5 0.5 0.005" mesh="tactile_sphere1" pos="-0.0005 0 0" quat="0.707107 0 0.707107 0"/>-->
<!--                                    </body>-->
<!--            -->
<!--            -->
<!--                                    <body name="touch_10_6_1" pos=" 0.00414 0.00248 0.024 "  euler=" 0.0 0.0 -0.485">\-->
<!--                     -->
<!--                                    <geom name="touch_10_6_1"   class="robot0:Tactile" friction="0.5 0.5 0.005" mesh="tactile_sphere1" pos="-0.0005 0 0" quat="0.707107 0 0.707107 0"/>-->
<!--                                    <geom name="touch_10_6_1"   class="robot0:D_Contact" friction="0.5 0.5 0.005" mesh="tactile_sphere1" pos="-0.0005 0 0" quat="0.707107 0 0.707107 0"/>-->
<!--                                    </body>-->
<!--            -->
<!--                                    <body name="touch_10_1_2" pos=" 0.00414 0.01752 0.02 "  euler=" 0.0 0.0 0.485">\-->
<!--                     -->
<!--                                    <geom name="touch_10_1_2"   class="robot0:Tactile" friction="0.5 0.5 0.005" mesh="tactile_sphere1" pos="-0.0005 0 0" quat="0.707107 0 0.707107 0"/>-->
<!--                                    <geom name="touch_10_1_2"   class="robot0:D_Contact" friction="0.5 0.5 0.005" mesh="tactile_sphere1" pos="-0.0005 0 0" quat="0.707107 0 0.707107 0"/>-->
<!--                                    </body>-->
<!--            -->
<!--                                    <body name="touch_10_2_2" pos=" 0.005265 0.01463 0.02 "  euler=" 0.0 0.0 0.1777">\-->
<!--                     -->
<!--                                    <geom name="touch_10_2_2"   class="robot0:Tactile" friction="0.5 0.5 0.005" mesh="tactile_sphere1" pos="-0.0005 0 0" quat="0.707107 0 0.707107 0"/>-->
<!--                                    <geom name="touch_10_2_2"   class="robot0:D_Contact" friction="0.5 0.5 0.005" mesh="tactile_sphere1" pos="-0.0005 0 0" quat="0.707107 0 0.707107 0"/>-->
<!--                                    </body>-->
<!--            -->
<!--                                    <body name="touch_10_3_2" pos=" 0.00581 0.01154 0.02"  euler=" 0.0 0.0 0.0">\-->
<!--                     -->
<!--                                    <geom name="touch_10_3_2"   class="robot0:Tactile" friction="0.5 0.5 0.005" mesh="tactile_sphere1" pos="-0.0005 0 0" quat="0.707107 0 0.707107 0"/>-->
<!--                                    <geom name="touch_10_3_2"   class="robot0:D_Contact" friction="0.5 0.5 0.005" mesh="tactile_sphere1" pos="-0.0005 0 0" quat="0.707107 0 0.707107 0"/>-->
<!--                                    </body>-->
<!--            -->
<!--                                    <body name="touch_10_4_2" pos=" 0.00581 0.00846 0.02 "  euler=" 0.0 0.0 0.0">\-->
<!--                     -->
<!--                                    <geom name="touch_10_4_2"   class="robot0:Tactile" friction="0.5 0.5 0.005" mesh="tactile_sphere1" pos="-0.0005 0 0" quat="0.707107 0 0.707107 0"/>-->
<!--                                    <geom name="touch_10_4_2"   class="robot0:D_Contact" friction="0.5 0.5 0.005" mesh="tactile_sphere1" pos="-0.0005 0 0" quat="0.707107 0 0.707107 0"/>-->
<!--                                    </body>-->
<!--            -->
<!--                                    <body name="touch_10_5_2" pos=" 0.005265 0.00537 0.02 "  euler=" 0.0 0.0 -0.1777">\-->
<!--                     -->
<!--                                    <geom name="touch_10_5_2"   class="robot0:Tactile" friction="0.5 0.5 0.005" mesh="tactile_sphere1" pos="-0.0005 0 0" quat="0.707107 0 0.707107 0"/>-->
<!--                                    <geom name="touch_10_5_2"   class="robot0:D_Contact" friction="0.5 0.5 0.005" mesh="tactile_sphere1" pos="-0.0005 0 0" quat="0.707107 0 0.707107 0"/>-->
<!--                                    </body>-->
<!--            -->
<!--                                    <body name="touch_10_6_2" pos=" 0.00414 0.00248 0.02 "  euler=" 0.0 0.0 -0.485">\-->
<!--                     -->
<!--                                    <geom name="touch_10_6_2"   class="robot0:Tactile" friction="0.5 0.5 0.005" mesh="tactile_sphere1" pos="-0.0005 0 0" quat="0.707107 0 0.707107 0"/>-->
<!--                                    <geom name="touch_10_6_2"   class="robot0:D_Contact" friction="0.5 0.5 0.005" mesh="tactile_sphere1" pos="-0.0005 0 0" quat="0.707107 0 0.707107 0"/>-->
<!--                                    </body>-->
<!--            -->
<!--                                    <body name="touch_10_1_3" pos=" 0.00414 0.01752 0.016 "  euler=" 0.0 0.0 0.485">\-->
<!--                     -->
<!--                                    <geom name="touch_10_1_3"   class="robot0:Tactile" friction="0.5 0.5 0.005" mesh="tactile_sphere1" pos="-0.0005 0 0" quat="0.707107 0 0.707107 0"/>-->
<!--                                    <geom name="touch_10_1_3"   class="robot0:D_Contact" friction="0.5 0.5 0.005" mesh="tactile_sphere1" pos="-0.0005 0 0" quat="0.707107 0 0.707107 0"/>-->
<!--                                    </body>-->
<!--            -->
<!--                                    <body name="touch_10_2_3" pos=" 0.005265 0.01463 0.016 "  euler=" 0.0 0.0 0.1777">\-->
<!--                     -->
<!--                                    <geom name="touch_10_2_3"   class="robot0:Tactile" friction="0.5 0.5 0.005" mesh="tactile_sphere1" pos="-0.0005 0 0" quat="0.707107 0 0.707107 0"/>-->
<!--                                    <geom name="touch_10_2_3"   class="robot0:D_Contact" friction="0.5 0.5 0.005" mesh="tactile_sphere1" pos="-0.0005 0 0" quat="0.707107 0 0.707107 0"/>-->
<!--                                    </body>-->
<!--            -->
<!--                                    <body name="touch_10_3_3" pos=" 0.00581 0.01154 0.016"  euler=" 0.0 0.0 0.0">\-->
<!--                     -->
<!--                                    <geom name="touch_10_3_3"   class="robot0:Tactile" friction="0.5 0.5 0.005" mesh="tactile_sphere1" pos="-0.0005 0 0" quat="0.707107 0 0.707107 0"/>-->
<!--                                    <geom name="touch_10_3_3"   class="robot0:D_Contact" friction="0.5 0.5 0.005" mesh="tactile_sphere1" pos="-0.0005 0 0" quat="0.707107 0 0.707107 0"/>-->
<!--                                    </body>-->
<!--            -->
<!--                                    <body name="touch_10_4_3" pos=" 0.00581 0.00846 0.016 "  euler=" 0.0 0.0 0.0">\-->
<!--                     -->
<!--                                    <geom name="touch_10_4_3"   class="robot0:Tactile" friction="0.5 0.5 0.005" mesh="tactile_sphere1" pos="-0.0005 0 0" quat="0.707107 0 0.707107 0"/>-->
<!--                                    <geom name="touch_10_4_3"   class="robot0:D_Contact" friction="0.5 0.5 0.005" mesh="tactile_sphere1" pos="-0.0005 0 0" quat="0.707107 0 0.707107 0"/>-->
<!--                                    </body>-->
<!--            -->
<!--                                    <body name="touch_10_5_3" pos=" 0.005265 0.00537 0.016 "  euler=" 0.0 0.0 -0.1777">\-->
<!--                     -->
<!--                                    <geom name="touch_10_5_3"   class="robot0:Tactile" friction="0.5 0.5 0.005" mesh="tactile_sphere1" pos="-0.0005 0 0" quat="0.707107 0 0.707107 0"/>-->
<!--                                    <geom name="touch_10_5_3"   class="robot0:D_Contact" friction="0.5 0.5 0.005" mesh="tactile_sphere1" pos="-0.0005 0 0" quat="0.707107 0 0.707107 0"/>-->
<!--                                    </body>-->
<!--            -->
<!--                                    <body name="touch_10_6_3" pos=" 0.00414 0.00248 0.016 "  euler=" 0.0 0.0 -0.485">\-->
<!--                     -->
<!--                                    <geom name="touch_10_6_3"   class="robot0:Tactile" friction="0.5 0.5 0.005" mesh="tactile_sphere1" pos="-0.0005 0 0" quat="0.707107 0 0.707107 0"/>-->
<!--                                    <geom name="touch_10_6_3"   class="robot0:D_Contact" friction="0.5 0.5 0.005" mesh="tactile_sphere1" pos="-0.0005 0 0" quat="0.707107 0 0.707107 0"/>-->
<!--                                    </body>-->
<!--            -->
<!--            -->
<!--                                    <body name="touch_10_1_4" pos=" 0.00414 0.01752 0.012 "  euler=" 0.0 0.0 0.485">\-->
<!--                     -->
<!--                                    <geom name="touch_10_1_4"   class="robot0:Tactile" friction="0.5 0.5 0.005" mesh="tactile_sphere1" pos="-0.0005 0 0" quat="0.707107 0 0.707107 0"/>-->
<!--                                    <geom name="touch_10_1_4"   class="robot0:D_Contact" friction="0.5 0.5 0.005" mesh="tactile_sphere1" pos="-0.0005 0 0" quat="0.707107 0 0.707107 0"/>-->
<!--                                    </body>-->
<!--            -->
<!--                                    <body name="touch_10_2_4" pos=" 0.005265 0.01463 0.012 "  euler=" 0.0 0.0 0.1777">\-->
<!--                     -->
<!--                                    <geom name="touch_10_2_4"   class="robot0:Tactile" friction="0.5 0.5 0.005" mesh="tactile_sphere1" pos="-0.0005 0 0" quat="0.707107 0 0.707107 0"/>-->
<!--                                    <geom name="touch_10_2_4"   class="robot0:D_Contact" friction="0.5 0.5 0.005" mesh="tactile_sphere1" pos="-0.0005 0 0" quat="0.707107 0 0.707107 0"/>-->
<!--                                    </body>-->
<!--            -->
<!--                                    <body name="touch_10_3_4" pos=" 0.00581 0.01154 0.012"  euler=" 0.0 0.0 0.0">\-->
<!--                     -->
<!--                                    <geom name="touch_10_3_4"   class="robot0:Tactile" friction="0.5 0.5 0.005" mesh="tactile_sphere1" pos="-0.0005 0 0" quat="0.707107 0 0.707107 0"/>-->
<!--                                    <geom name="touch_10_3_4"   class="robot0:D_Contact" friction="0.5 0.5 0.005" mesh="tactile_sphere1" pos="-0.0005 0 0" quat="0.707107 0 0.707107 0"/>-->
<!--                                    </body>-->
<!--            -->
<!--                                    <body name="touch_10_4_4" pos=" 0.00581 0.00846 0.012 "  euler=" 0.0 0.0 0.0">\-->
<!--                     -->
<!--                                    <geom name="touch_10_4_4"   class="robot0:Tactile" friction="0.5 0.5 0.005" mesh="tactile_sphere1" pos="-0.0005 0 0" quat="0.707107 0 0.707107 0"/>-->
<!--                                    <geom name="touch_10_4_4"   class="robot0:D_Contact" friction="0.5 0.5 0.005" mesh="tactile_sphere1" pos="-0.0005 0 0" quat="0.707107 0 0.707107 0"/>-->
<!--                                    </body>-->
<!--            -->
<!--                                    <body name="touch_10_5_4" pos=" 0.005265 0.00537 0.012 "  euler=" 0.0 0.0 -0.1777">\-->
<!--                     -->
<!--                                    <geom name="touch_10_5_4"   class="robot0:Tactile" friction="0.5 0.5 0.005" mesh="tactile_sphere1" pos="-0.0005 0 0" quat="0.707107 0 0.707107 0"/>-->
<!--                                    <geom name="touch_10_5_4"   class="robot0:D_Contact" friction="0.5 0.5 0.005" mesh="tactile_sphere1" pos="-0.0005 0 0" quat="0.707107 0 0.707107 0"/>-->
<!--                                    </body>-->
<!--            -->
<!--                                    <body name="touch_10_6_4" pos=" 0.00414 0.00248 0.012 "  euler=" 0.0 0.0 -0.485">\-->
<!--                     -->
<!--                                    <geom name="touch_10_6_4"   class="robot0:Tactile" friction="0.5 0.5 0.005" mesh="tactile_sphere1" pos="-0.0005 0 0" quat="0.707107 0 0.707107 0"/>-->
<!--                                    <geom name="touch_10_6_4"   class="robot0:D_Contact" friction="0.5 0.5 0.005" mesh="tactile_sphere1" pos="-0.0005 0 0" quat="0.707107 0 0.707107 0"/>-->
<!--                                    </body>-->
<!--            -->
<!--            -->
<!--                                    <body name="touch_10_1_5" pos=" 0.00414 0.01752 0.008 "  euler=" 0.0 0.0 0.485">\-->
<!--                     -->
<!--                                    <geom name="touch_10_1_5"   class="robot0:Tactile" friction="0.5 0.5 0.005" mesh="tactile_sphere1" pos="-0.0005 0 0" quat="0.707107 0 0.707107 0"/>-->
<!--                                    <geom name="touch_10_1_5"   class="robot0:D_Contact" friction="0.5 0.5 0.005" mesh="tactile_sphere1" pos="-0.0005 0 0" quat="0.707107 0 0.707107 0"/>-->
<!--                                    </body>-->
<!--            -->
<!--                                    <body name="touch_10_2_5" pos=" 0.005265 0.01463 0.008 "  euler=" 0.0 0.0 0.1777">\-->
<!--                     -->
<!--                                    <geom name="touch_10_2_5"   class="robot0:Tactile" friction="0.5 0.5 0.005" mesh="tactile_sphere1" pos="-0.0005 0 0" quat="0.707107 0 0.707107 0"/>-->
<!--                                    <geom name="touch_10_2_5"   class="robot0:D_Contact" friction="0.5 0.5 0.005" mesh="tactile_sphere1" pos="-0.0005 0 0" quat="0.707107 0 0.707107 0"/>-->
<!--                                    </body>-->
<!--            -->
<!--                                    <body name="touch_10_3_5" pos=" 0.00581 0.01154 0.008"  euler=" 0.0 0.0 0.0">\-->
<!--                     -->
<!--                                    <geom name="touch_10_3_5"   class="robot0:Tactile" friction="0.5 0.5 0.005" mesh="tactile_sphere1" pos="-0.0005 0 0" quat="0.707107 0 0.707107 0"/>-->
<!--                                    <geom name="touch_10_3_5"   class="robot0:D_Contact" friction="0.5 0.5 0.005" mesh="tactile_sphere1" pos="-0.0005 0 0" quat="0.707107 0 0.707107 0"/>-->
<!--                                    </body>-->
<!--            -->
<!--                                    <body name="touch_10_4_5" pos=" 0.00581 0.00846 0.008 "  euler=" 0.0 0.0 0.0">\-->
<!--                     -->
<!--                                    <geom name="touch_10_4_5"   class="robot0:Tactile" friction="0.5 0.5 0.005" mesh="tactile_sphere1" pos="-0.0005 0 0" quat="0.707107 0 0.707107 0"/>-->
<!--                                    <geom name="touch_10_4_5"   class="robot0:D_Contact" friction="0.5 0.5 0.005" mesh="tactile_sphere1" pos="-0.0005 0 0" quat="0.707107 0 0.707107 0"/>-->
<!--                                    </body>-->
<!--            -->
<!--                                    <body name="touch_10_5_5" pos=" 0.005265 0.00537 0.008 "  euler=" 0.0 0.0 -0.1777">\-->
<!--                     -->
<!--                                    <geom name="touch_10_5_5"   class="robot0:Tactile" friction="0.5 0.5 0.005" mesh="tactile_sphere1" pos="-0.0005 0 0" quat="0.707107 0 0.707107 0"/>-->
<!--                                    <geom name="touch_10_5_5"   class="robot0:D_Contact" friction="0.5 0.5 0.005" mesh="tactile_sphere1" pos="-0.0005 0 0" quat="0.707107 0 0.707107 0"/>-->
<!--                                    </body>-->
<!--            -->
<!--                                    <body name="touch_10_6_5" pos=" 0.00414 0.00248 0.008 "  euler=" 0.0 0.0 -0.485">\-->
<!--                     -->
<!--                                    <geom name="touch_10_6_5"   class="robot0:Tactile" friction="0.5 0.5 0.005" mesh="tactile_sphere1" pos="-0.0005 0 0" quat="0.707107 0 0.707107 0"/>-->
<!--                                    <geom name="touch_10_6_5"   class="robot0:D_Contact" friction="0.5 0.5 0.005" mesh="tactile_sphere1" pos="-0.0005 0 0" quat="0.707107 0 0.707107 0"/>-->
<!--                                    </body>-->
<!--            -->
<!--            -->
<!--                                    <body name="touch_10_1_6" pos=" 0.00414 0.01752 0.004 "  euler=" 0.0 0.0 0.485">\-->
<!--                     -->
<!--                                    <geom name="touch_10_1_6"   class="robot0:Tactile" friction="0.5 0.5 0.005" mesh="tactile_sphere1" pos="-0.0005 0 0" quat="0.707107 0 0.707107 0"/>-->
<!--                                    <geom name="touch_10_1_6"   class="robot0:D_Contact" friction="0.5 0.5 0.005" mesh="tactile_sphere1" pos="-0.0005 0 0" quat="0.707107 0 0.707107 0"/>-->
<!--                                    </body>-->
<!--            -->
<!--                                    <body name="touch_10_2_6" pos=" 0.005265 0.01463 0.004 "  euler=" 0.0 0.0 0.1777">\-->
<!--                     -->
<!--                                    <geom name="touch_10_2_6"   class="robot0:Tactile" friction="0.5 0.5 0.005" mesh="tactile_sphere1" pos="-0.0005 0 0" quat="0.707107 0 0.707107 0"/>-->
<!--                                    <geom name="touch_10_2_6"   class="robot0:D_Contact" friction="0.5 0.5 0.005" mesh="tactile_sphere1" pos="-0.0005 0 0" quat="0.707107 0 0.707107 0"/>-->
<!--                                    </body>-->
<!--            -->
<!--                                    <body name="touch_10_3_6" pos=" 0.00581 0.01154 0.004"  euler=" 0.0 0.0 0.0">\-->
<!--                     -->
<!--                                    <geom name="touch_10_3_6"   class="robot0:Tactile" friction="0.5 0.5 0.005" mesh="tactile_sphere1" pos="-0.0005 0 0" quat="0.707107 0 0.707107 0"/>-->
<!--                                    <geom name="touch_10_3_6"   class="robot0:D_Contact" friction="0.5 0.5 0.005" mesh="tactile_sphere1" pos="-0.0005 0 0" quat="0.707107 0 0.707107 0"/>-->
<!--                                    </body>-->
<!--            -->
<!--                                    <body name="touch_10_4_6" pos=" 0.00581 0.00846 0.004 "  euler=" 0.0 0.0 0.0">\-->
<!--                     -->
<!--                                    <geom name="touch_10_4_6"   class="robot0:Tactile" friction="0.5 0.5 0.005" mesh="tactile_sphere1" pos="-0.0005 0 0" quat="0.707107 0 0.707107 0"/>-->
<!--                                    <geom name="touch_10_4_6"   class="robot0:D_Contact" friction="0.5 0.5 0.005" mesh="tactile_sphere1" pos="-0.0005 0 0" quat="0.707107 0 0.707107 0"/>-->
<!--                                    </body>-->
<!--            -->
<!--                                    <body name="touch_10_5_6" pos=" 0.005265 0.00537 0.004 "  euler=" 0.0 0.0 -0.1777">\-->
<!--                     -->
<!--                                    <geom name="touch_10_5_6"   class="robot0:Tactile" friction="0.5 0.5 0.005" mesh="tactile_sphere1" pos="-0.0005 0 0" quat="0.707107 0 0.707107 0"/>-->
<!--                                    <geom name="touch_10_5_6"   class="robot0:D_Contact" friction="0.5 0.5 0.005" mesh="tactile_sphere1" pos="-0.0005 0 0" quat="0.707107 0 0.707107 0"/>-->
<!--                                    </body>-->
<!--            -->
<!--                                    <body name="touch_10_6_6" pos=" 0.00414 0.00248 0.004 "  euler=" 0.0 0.0 -0.485">\-->
<!--                     -->
<!--                                    <geom name="touch_10_6_6"   class="robot0:Tactile" friction="0.5 0.5 0.005" mesh="tactile_sphere1" pos="-0.0005 0 0" quat="0.707107 0 0.707107 0"/>-->
<!--                                    <geom name="touch_10_6_6"   class="robot0:D_Contact" friction="0.5 0.5 0.005" mesh="tactile_sphere1" pos="-0.0005 0 0" quat="0.707107 0 0.707107 0"/>-->
<!--                                    </body>-->
<!--            -->
<!--                                </body>-->

                                </body>

                                <!-- finger tip -->
                                <body name="link_15.0_tip" pos="0.002 0 0.0313">
                                    <geom class="robot0:Pad" pos="0 0 0" rgba="0.9 0.9 0.9 1" type="mesh" mesh="link_15.0_tip"  euler="0 0 0"/>
                                    <geom class="robot0:D_Contact" pos="0 0 0" rgba="0.9 0.9 0.9 1" type="mesh" mesh="link_15.0_tip"  euler="0 0 0"/>

                                </body>
                            </body>
                        </body>
                    </body>
                </body>

    </body>
</mujoco>
